Workbook

Sheet Overview
J2: Results
J3: 11 Sep to 2 Oct 2026
B6: ALL CALLS | E6: BETS | H6: LAYS
B7: =SUM('All Calls'!$N$6:$N$790) | E7: =SUMIFS('All Calls'!$N$6:$N$790,'All Calls'!$F$6:$F$790,"Bet") | H7: =SUMIFS('All Calls'!$N$6:$N$790,'All Calls'!$F$6:$F$790,"Lay")
B9: =COUNTIFS('All Calls'!$M$6:$M$790,"Win")+COUNTIFS('All Calls'!$M$6:$M$790,"Loss")&" settled, "&TEXT(COUNTIFS('All Calls'!$M$6:$M$790,"Win")/(COUNTIFS('All Calls'!$M$6:$M$790,"Win")+COUNTIFS('All Calls'!$M$6:$M$790,"Loss")),"0%")&" strike, "&TEXT(IF(SUM('All Calls'!$O$6:$O$790)=0,0,B7/SUM('All Calls'!$O$6:$O$790)),"+0.0%;-0.0%")&" ROI" | E9: =COUNTIFS('All Calls'!$M$6:$M$790,"Win",'All Calls'!$F$6:$F$790,"Bet")+COUNTIFS('All Calls'!$M$6:$M$790,"Loss",'All Calls'!$F$6:$F$790,"Bet")&" settled, "&TEXT(COUNTIFS('All Calls'!$M$6:$M$790,"Win",'All Calls'!$F$6:$F$790,"Bet")/(COUNTIFS('All Calls'!$M$6:$M$790,"Win",'All Calls'!$F$6:$F$790,"Bet")+COUNTIFS('All Calls'!$M$6:$M$790,"Loss",'All Calls'!$F$6:$F$790,"Bet")),"0%")&" strike, "&TEXT(IF(SUMIFS('All Calls'!$O$6:$O$790,'All Calls'!$F$6:$F$790,"Bet")=0,0,E7/SUMIFS('All Calls'!$O$6:$O$790,'All Calls'!$F$6:$F$790,"Bet")),"+0.0%;-0.0%")&" ROI" | H9: =COUNTIFS('All Calls'!$M$6:$M$790,"Win",'All Calls'!$F$6:$F$790,"Lay")+COUNTIFS('All Calls'!$M$6:$M$790,"Loss",'All Calls'!$F$6:$F$790,"Lay")&" settled, "&TEXT(COUNTIFS('All Calls'!$M$6:$M$790,"Win",'All Calls'!$F$6:$F$790,"Lay")/(COUNTIFS('All Calls'!$M$6:$M$790,"Win",'All Calls'!$F$6:$F$790,"Lay")+COUNTIFS('All Calls'!$M$6:$M$790,"Loss",'All Calls'!$F$6:$F$790,"Lay")),"0%")&" strike, "&TEXT(IF(SUMIFS('All Calls'!$O$6:$O$790,'All Calls'!$F$6:$F$790,"Lay")=0,0,H7/SUMIFS('All Calls'!$O$6:$O$790,'All Calls'!$F$6:$F$790,"Lay")),"+0.0%;-0.0%")&" ROI"
A11: Level stakes: one unit a call, a tenth on a Way. Bets settle at the best of fixed odds, SP and BSP; lays at the shortest lay price or BSP.
A12: A lay wins one unit when the horse loses and risks the price less one. ROI is profit over units at risk. Scratchings and abandoned races are void.
A13: Bets at $10 or more from 11 to 15 Sep are excluded: our ratings over-priced long shots until the 15 Sep fix.
A14: BY CALL
B15: Calls | C15: Won | D15: Lost | E15: Void | F15: Pending | G15: Strike | H15: Profit (u) | I15: At risk (u) | J15: ROI
A16: All calls | B16: =COUNTIFS('All Calls'!$M$6:$M$790,"<>") | C16: =COUNTIFS('All Calls'!$M$6:$M$790,"Win") | D16: =COUNTIFS('All Calls'!$M$6:$M$790,"Loss") | E16: =COUNTIFS('All Calls'!$M$6:$M$790,"Void") | F16: =COUNTIFS('All Calls'!$M$6:$M$790,"Pending") | G16: =IF(C16+D16=0,"",C16/(C16+D16)) | H16: =SUM('All Calls'!$N$6:$N$790) | I16: =SUM('All Calls'!$O$6:$O$790) | J16: =IF(I16=0,"",H16/I16)
A17: Bets | B17: =COUNTIFS('All Calls'!$M$6:$M$790,"<>",'All Calls'!$F$6:$F$790,"Bet") | C17: =COUNTIFS('All Calls'!$M$6:$M$790,"Win",'All Calls'!$F$6:$F$790,"Bet") | D17: =COUNTIFS('All Calls'!$M$6:$M$790,"Loss",'All Calls'!$F$6:$F$790,"Bet") | E17: =COUNTIFS('All Calls'!$M$6:$M$790,"Void",'All Calls'!$F$6:$F$790,"Bet") | F17: =COUNTIFS('All Calls'!$M$6:$M$790,"Pending",'All Calls'!$F$6:$F$790,"Bet") | G17: =IF(C17+D17=0,"",C17/(C17+D17)) | H17: =SUMIFS('All Calls'!$N$6:$N$790,'All Calls'!$F$6:$F$790,"Bet") | I17: =SUMIFS('All Calls'!$O$6:$O$790,'All Calls'!$F$6:$F$790,"Bet") | J17: =IF(I17=0,"",H17/I17)
A18: Lays | B18: =COUNTIFS('All Calls'!$M$6:$M$790,"<>",'All Calls'!$F$6:$F$790,"Lay") | C18: =COUNTIFS('All Calls'!$M$6:$M$790,"Win",'All Calls'!$F$6:$F$790,"Lay") | D18: =COUNTIFS('All Calls'!$M$6:$M$790,"Loss",'All Calls'!$F$6:$F$790,"Lay") | E18: =COUNTIFS('All Calls'!$M$6:$M$790,"Void",'All Calls'!$F$6:$F$790,"Lay") | F18: =COUNTIFS('All Calls'!$M$6:$M$790,"Pending",'All Calls'!$F$6:$F$790,"Lay") | G18: =IF(C18+D18=0,"",C18/(C18+D18)) | H18: =SUMIFS('All Calls'!$N$6:$N$790,'All Calls'!$F$6:$F$790,"Lay") | I18: =SUMIFS('All Calls'!$O$6:$O$790,'All Calls'!$F$6:$F$790,"Lay") | J18: =IF(I18=0,"",H18/I18)
A20: BY TAG
A21: Tag | B21: Calls | C21: Won | D21: Lost | E21: Void | F21: Pending | G21: Strike | H21: Profit (u) | I21: At risk (u) | J21: ROI
A22: Prime | B22: =COUNTIFS('All Calls'!$M$6:$M$790,"<>",'All Calls'!$G$6:$G$790,"Prime") | C22: =COUNTIFS('All Calls'!$M$6:$M$790,"Win",'All Calls'!$G$6:$G$790,"Prime") | D22: =COUNTIFS('All Calls'!$M$6:$M$790,"Loss",'All Calls'!$G$6:$G$790,"Prime") | E22: =COUNTIFS('All Calls'!$M$6:$M$790,"Void",'All Calls'!$G$6:$G$790,"Prime") | F22: =COUNTIFS('All Calls'!$M$6:$M$790,"Pending",'All Calls'!$G$6:$G$790,"Prime") | G22: =IF(C22+D22=0,"",C22/(C22+D22)) | H22: =SUMIFS('All Calls'!$N$6:$N$790,'All Calls'!$G$6:$G$790,"Prime") | I22: =SUMIFS('All Calls'!$O$6:$O$790,'All Calls'!$G$6:$G$790,"Prime") | J22: =IF(I22=0,"",H22/I22)
A23: Bet | B23: =COUNTIFS('All Calls'!$M$6:$M$790,"<>",'All Calls'!$G$6:$G$790,"Bet") | C23: =COUNTIFS('All Calls'!$M$6:$M$790,"Win",'All Calls'!$G$6:$G$790,"Bet") | D23: =COUNTIFS('All Calls'!$M$6:$M$790,"Loss",'All Calls'!$G$6:$G$790,"Bet") | E23: =COUNTIFS('All Calls'!$M$6:$M$790,"Void",'All Calls'!$G$6:$G$790,"Bet") | F23: =COUNTIFS('All Calls'!$M$6:$M$790,"Pending",'All Calls'!$G$6:$G$790,"Bet") | G23: =IF(C23+D23=0,"",C23/(C23+D23)) | H23: =SUMIFS('All Calls'!$N$6:$N$790,'All Calls'!$G$6:$G$790,"Bet") | I23: =SUMIFS('All Calls'!$O$6:$O$790,'All Calls'!$G$6:$G$790,"Bet") | J23: =IF(I23=0,"",H23/I23)
A24: Way | B24: =COUNTIFS('All Calls'!$M$6:$M$790,"<>",'All Calls'!$G$6:$G$790,"Way") | C24: =COUNTIFS('All Calls'!$M$6:$M$790,"Win",'All Calls'!$G$6:$G$790,"Way") | D24: =COUNTIFS('All Calls'!$M$6:$M$790,"Loss",'All Calls'!$G$6:$G$790,"Way") | E24: =COUNTIFS('All Calls'!$M$6:$M$790,"Void",'All Calls'!$G$6:$G$790,"Way") | F24: =COUNTIFS('All Calls'!$M$6:$M$790,"Pending",'All Calls'!$G$6:$G$790,"Way") | G24: =IF(C24+D24=0,"",C24/(C24+D24)) | H24: =SUMIFS('All Calls'!$N$6:$N$790,'All Calls'!$G$6:$G$790,"Way") | I24: =SUMIFS('All Calls'!$O$6:$O$790,'All Calls'!$G$6:$G$790,"Way") | J24: =IF(I24=0,"",H24/I24)
A25: Lay | B25: =COUNTIFS('All Calls'!$M$6:$M$790,"<>",'All Calls'!$G$6:$G$790,"Lay") | C25: =COUNTIFS('All Calls'!$M$6:$M$790,"Win",'All Calls'!$G$6:$G$790,"Lay") | D25: =COUNTIFS('All Calls'!$M$6:$M$790,"Loss",'All Calls'!$G$6:$G$790,"Lay") | E25: =COUNTIFS('All Calls'!$M$6:$M$790,"Void",'All Calls'!$G$6:$G$790,"Lay") | F25: =COUNTIFS('All Calls'!$M$6:$M$790,"Pending",'All Calls'!$G$6:$G$790,"Lay") | G25: =IF(C25+D25=0,"",C25/(C25+D25)) | H25: =SUMIFS('All Calls'!$N$6:$N$790,'All Calls'!$G$6:$G$790,"Lay") | I25: =SUMIFS('All Calls'!$O$6:$O$790,'All Calls'!$G$6:$G$790,"Lay") | J25: =IF(I25=0,"",H25/I25)
A27: BY WEEK
A28: Week of | B28: Calls | C28: Won | D28: Lost | E28: Void | F28: Pending | G28: Strike | H28: Profit (u) | I28: At risk (u) | J28: ROI
A29: 46272 | B29: =COUNTIFS('All Calls'!$M$6:$M$790,"<>",'All Calls'!$A$6:$A$790,">="&$A29,'All Calls'!$A$6:$A$790,"<"&($A29+7)) | C29: =COUNTIFS('All Calls'!$M$6:$M$790,"Win",'All Calls'!$A$6:$A$790,">="&$A29,'All Calls'!$A$6:$A$790,"<"&($A29+7)) | D29: =COUNTIFS('All Calls'!$M$6:$M$790,"Loss",'All Calls'!$A$6:$A$790,">="&$A29,'All Calls'!$A$6:$A$790,"<"&($A29+7)) | E29: =COUNTIFS('All Calls'!$M$6:$M$790,"Void",'All Calls'!$A$6:$A$790,">="&$A29,'All Calls'!$A$6:$A$790,"<"&($A29+7)) | F29: =COUNTIFS('All Calls'!$M$6:$M$790,"Pending",'All Calls'!$A$6:$A$790,">="&$A29,'All Calls'!$A$6:$A$790,"<"&($A29+7)) | G29: =IF(C29+D29=0,"",C29/(C29+D29)) | H29: =SUMIFS('All Calls'!$N$6:$N$790,'All Calls'!$A$6:$A$790,">="&$A29,'All Calls'!$A$6:$A$790,"<"&($A29+7)) | I29: =SUMIFS('All Calls'!$O$6:$O$790,'All Calls'!$A$6:$A$790,">="&$A29,'All Calls'!$A$6:$A$790,"<"&($A29+7)) | J29: =IF(I29=0,"",H29/I29)
A30: 46279 | B30: =COUNTIFS('All Calls'!$M$6:$M$790,"<>",'All Calls'!$A$6:$A$790,">="&$A30,'All Calls'!$A$6:$A$790,"<"&($A30+7)) | C30: =COUNTIFS('All Calls'!$M$6:$M$790,"Win",'All Calls'!$A$6:$A$790,">="&$A30,'All Calls'!$A$6:$A$790,"<"&($A30+7)) | D30: =COUNTIFS('All Calls'!$M$6:$M$790,"Loss",'All Calls'!$A$6:$A$790,">="&$A30,'All Calls'!$A$6:$A$790,"<"&($A30+7)) | E30: =COUNTIFS('All Calls'!$M$6:$M$790,"Void",'All Calls'!$A$6:$A$790,">="&$A30,'All Calls'!$A$6:$A$790,"<"&($A30+7)) | F30: =COUNTIFS('All Calls'!$M$6:$M$790,"Pending",'All Calls'!$A$6:$A$790,">="&$A30,'All Calls'!$A$6:$A$790,"<"&($A30+7)) | G30: =IF(C30+D30=0,"",C30/(C30+D30)) | H30: =SUMIFS('All Calls'!$N$6:$N$790,'All Calls'!$A$6:$A$790,">="&$A30,'All Calls'!$A$6:$A$790,"<"&($A30+7)) | I30: =SUMIFS('All Calls'!$O$6:$O$790,'All Calls'!$A$6:$A$790,">="&$A30,'All Calls'!$A$6:$A$790,"<"&($A30+7)) | J30: =IF(I30=0,"",H30/I30)
A31: 46286 | B31: =COUNTIFS('All Calls'!$M$6:$M$790,"<>",'All Calls'!$A$6:$A$790,">="&$A31,'All Calls'!$A$6:$A$790,"<"&($A31+7)) | C31: =COUNTIFS('All Calls'!$M$6:$M$790,"Win",'All Calls'!$A$6:$A$790,">="&$A31,'All Calls'!$A$6:$A$790,"<"&($A31+7)) | D31: =COUNTIFS('All Calls'!$M$6:$M$790,"Loss",'All Calls'!$A$6:$A$790,">="&$A31,'All Calls'!$A$6:$A$790,"<"&($A31+7)) | E31: =COUNTIFS('All Calls'!$M$6:$M$790,"Void",'All Calls'!$A$6:$A$790,">="&$A31,'All Calls'!$A$6:$A$790,"<"&($A31+7)) | F31: =COUNTIFS('All Calls'!$M$6:$M$790,"Pending",'All Calls'!$A$6:$A$790,">="&$A31,'All Calls'!$A$6:$A$790,"<"&($A31+7)) | G31: =IF(C31+D31=0,"",C31/(C31+D31)) | H31: =SUMIFS('All Calls'!$N$6:$N$790,'All Calls'!$A$6:$A$790,">="&$A31,'All Calls'!$A$6:$A$790,"<"&($A31+7)) | I31: =SUMIFS('All Calls'!$O$6:$O$790,'All Calls'!$A$6:$A$790,">="&$A31,'All Calls'!$A$6:$A$790,"<"&($A31+7)) | J31: =IF(I31=0,"",H31/I31)
A32: 46293 | B32: =COUNTIFS('All Calls'!$M$6:$M$790,"<>",'All Calls'!$A$6:$A$790,">="&$A32,'All Calls'!$A$6:$A$790,"<"&($A32+7)) | C32: =COUNTIFS('All Calls'!$M$6:$M$790,"Win",'All Calls'!$A$6:$A$790,">="&$A32,'All Calls'!$A$6:$A$790,"<"&($A32+7)) | D32: =COUNTIFS('All Calls'!$M$6:$M$790,"Loss",'All Calls'!$A$6:$A$790,">="&$A32,'All Calls'!$A$6:$A$790,"<"&($A32+7)) | E32: =COUNTIFS('All Calls'!$M$6:$M$790,"Void",'All Calls'!$A$6:$A$790,">="&$A32,'All Calls'!$A$6:$A$790,"<"&($A32+7)) | F32: =COUNTIFS('All Calls'!$M$6:$M$790,"Pending",'All Calls'!$A$6:$A$790,">="&$A32,'All Calls'!$A$6:$A$790,"<"&($A32+7)) | G32: =IF(C32+D32=0,"",C32/(C32+D32)) | H32: =SUMIFS('All Calls'!$N$6:$N$790,'All Calls'!$A$6:$A$790,">="&$A32,'All Calls'!$A$6:$A$790,"<"&($A32+7)) | I32: =SUMIFS('All Calls'!$O$6:$O$790,'All Calls'!$A$6:$A$790,">="&$A32,'All Calls'!$A$6:$A$790,"<"&($A32+7)) | J32: =IF(I32=0,"",H32/I32)
A34: BY DAY
A35: Date | B35: Settled | C35: Bets (u) | D35: Lays (u) | E35: Day (u) | F35: Running (u)
A36: 46276 | B36: =COUNTIFS('All Calls'!$A$6:$A$790,$A36,'All Calls'!$M$6:$M$790,"<>Pending") | C36: =SUMIFS('All Calls'!$N$6:$N$790,'All Calls'!$A$6:$A$790,$A36,'All Calls'!$F$6:$F$790,"Bet") | D36: =SUMIFS('All Calls'!$N$6:$N$790,'All Calls'!$A$6:$A$790,$A36,'All Calls'!$F$6:$F$790,"Lay") | E36: =C36+D36 | F36: =E36
A37: 46277 | B37: =COUNTIFS('All Calls'!$A$6:$A$790,$A37,'All Calls'!$M$6:$M$790,"<>Pending") | C37: =SUMIFS('All Calls'!$N$6:$N$790,'All Calls'!$A$6:$A$790,$A37,'All Calls'!$F$6:$F$790,"Bet") | D37: =SUMIFS('All Calls'!$N$6:$N$790,'All Calls'!$A$6:$A$790,$A37,'All Calls'!$F$6:$F$790,"Lay") | E37: =C37+D37 | F37: =F36+E37
A38: 46278 | B38: =COUNTIFS('All Calls'!$A$6:$A$790,$A38,'All Calls'!$M$6:$M$790,"<>Pending") | C38: =SUMIFS('All Calls'!$N$6:$N$790,'All Calls'!$A$6:$A$790,$A38,'All Calls'!$F$6:$F$790,"Bet") | D38: =SUMIFS('All Calls'!$N$6:$N$790,'All Calls'!$A$6:$A$790,$A38,'All Calls'!$F$6:$F$790,"Lay") | E38: =C38+D38 | F38: =F37+E38
A39: 46279 | B39: =COUNTIFS('All Calls'!$A$6:$A$790,$A39,'All Calls'!$M$6:$M$790,"<>Pending") | C39: =SUMIFS('All Calls'!$N$6:$N$790,'All Calls'!$A$6:$A$790,$A39,'All Calls'!$F$6:$F$790,"Bet") | D39: =SUMIFS('All Calls'!$N$6:$N$790,'All Calls'!$A$6:$A$790,$A39,'All Calls'!$F$6:$F$790,"Lay") | E39: =C39+D39 | F39: =F38+E39
A40: 46280 | B40: =COUNTIFS('All Calls'!$A$6:$A$790,$A40,'All Calls'!$M$6:$M$790,"<>Pending") | C40: =SUMIFS('All Calls'!$N$6:$N$790,'All Calls'!$A$6:$A$790,$A40,'All Calls'!$F$6:$F$790,"Bet") | D40: =SUMIFS('All Calls'!$N$6:$N$790,'All Calls'!$A$6:$A$790,$A40,'All Calls'!$F$6:$F$790,"Lay") | E40: =C40+D40 | F40: =F39+E40
A41: 46281 | B41: =COUNTIFS('All Calls'!$A$6:$A$790,$A41,'All Calls'!$M$6:$M$790,"<>Pending") | C41: =SUMIFS('All Calls'!$N$6:$N$790,'All Calls'!$A$6:$A$790,$A41,'All Calls'!$F$6:$F$790,"Bet") | D41: =SUMIFS('All Calls'!$N$6:$N$790,'All Calls'!$A$6:$A$790,$A41,'All Calls'!$F$6:$F$790,"Lay") | E41: =C41+D41 | F41: =F40+E41
A42: 46282 | B42: =COUNTIFS('All Calls'!$A$6:$A$790,$A42,'All Calls'!$M$6:$M$790,"<>Pending") | C42: =SUMIFS('All Calls'!$N$6:$N$790,'All Calls'!$A$6:$A$790,$A42,'All Calls'!$F$6:$F$790,"Bet") | D42: =SUMIFS('All Calls'!$N$6:$N$790,'All Calls'!$A$6:$A$790,$A42,'All Calls'!$F$6:$F$790,"Lay") | E42: =C42+D42 | F42: =F41+E42
A43: 46283 | B43: =COUNTIFS('All Calls'!$A$6:$A$790,$A43,'All Calls'!$M$6:$M$790,"<>Pending") | C43: =SUMIFS('All Calls'!$N$6:$N$790,'All Calls'!$A$6:$A$790,$A43,'All Calls'!$F$6:$F$790,"Bet") | D43: =SUMIFS('All Calls'!$N$6:$N$790,'All Calls'!$A$6:$A$790,$A43,'All Calls'!$F$6:$F$790,"Lay") | E43: =C43+D43 | F43: =F42+E43
A44: 46284 | B44: =COUNTIFS('All Calls'!$A$6:$A$790,$A44,'All Calls'!$M$6:$M$790,"<>Pending") | C44: =SUMIFS('All Calls'!$N$6:$N$790,'All Calls'!$A$6:$A$790,$A44,'All Calls'!$F$6:$F$790,"Bet") | D44: =SUMIFS('All Calls'!$N$6:$N$790,'All Calls'!$A$6:$A$790,$A44,'All Calls'!$F$6:$F$790,"Lay") | E44: =C44+D44 | F44: =F43+E44
A45: 46285 | B45: =COUNTIFS('All Calls'!$A$6:$A$790,$A45,'All Calls'!$M$6:$M$790,"<>Pending") | C45: =SUMIFS('All Calls'!$N$6:$N$790,'All Calls'!$A$6:$A$790,$A45,'All Calls'!$F$6:$F$790,"Bet") | D45: =SUMIFS('All Calls'!$N$6:$N$790,'All Calls'!$A$6:$A$790,$A45,'All Calls'!$F$6:$F$790,"Lay") | E45: =C45+D45 | F45: =F44+E45
A46: 46286 | B46: =COUNTIFS('All Calls'!$A$6:$A$790,$A46,'All Calls'!$M$6:$M$790,"<>Pending") | C46: =SUMIFS('All Calls'!$N$6:$N$790,'All Calls'!$A$6:$A$790,$A46,'All Calls'!$F$6:$F$790,"Bet") | D46: =SUMIFS('All Calls'!$N$6:$N$790,'All Calls'!$A$6:$A$790,$A46,'All Calls'!$F$6:$F$790,"Lay") | E46: =C46+D46 | F46: =F45+E46
A47: 46287 | B47: =COUNTIFS('All Calls'!$A$6:$A$790,$A47,'All Calls'!$M$6:$M$790,"<>Pending") | C47: =SUMIFS('All Calls'!$N$6:$N$790,'All Calls'!$A$6:$A$790,$A47,'All Calls'!$F$6:$F$790,"Bet") | D47: =SUMIFS('All Calls'!$N$6:$N$790,'All Calls'!$A$6:$A$790,$A47,'All Calls'!$F$6:$F$790,"Lay") | E47: =C47+D47 | F47: =F46+E47
A48: 46288 | B48: =COUNTIFS('All Calls'!$A$6:$A$790,$A48,'All Calls'!$M$6:$M$790,"<>Pending") | C48: =SUMIFS('All Calls'!$N$6:$N$790,'All Calls'!$A$6:$A$790,$A48,'All Calls'!$F$6:$F$790,"Bet") | D48: =SUMIFS('All Calls'!$N$6:$N$790,'All Calls'!$A$6:$A$790,$A48,'All Calls'!$F$6:$F$790,"Lay") | E48: =C48+D48 | F48: =F47+E48
...

Sheet All Calls
O2: All calls
O3: Every bet and lay, 11 Sep to 2 Oct 2026
A5: Date | B5: Track | C5: Race | D5: No. | E5: Horse | F5: Call | G5: Tag | H5: Rated $ | I5: Price $ | J5: Edge | K5: Stake (u) | L5: Finish | M5: Result | N5: Profit (u) | O5: At risk (u)
A6: 46276 | B6: Geelong | C6: 2 | D6: 5 | E6: Vespasian | F6: Bet | G6: Bet | H6: 6.3 | I6: 9.8 | J6: 0.0253 | K6: 1 | L6: 2 | M6: Loss | N6: =IF(M6="Win",IF(F6="Bet",(I6-1)*K6,K6),IF(M6="Loss",IF(F6="Bet",-K6,-(I6-1)*K6),IF(M6="Void",0,""))) | O6: =IF(OR(M6="Win",M6="Loss"),IF(F6="Bet",K6,(I6-1)*K6),"")
A7: 46276 | B7: Geelong | C7: 6 | D7: 10 | E7: Karren | F7: Lay | G7: Lay | H7: 2.85 | I7: 1.98 | J7: -0.1505 | K7: 1 | L7: 2 | M7: Win | N7: =IF(M7="Win",IF(F7="Bet",(I7-1)*K7,K7),IF(M7="Loss",IF(F7="Bet",-K7,-(I7-1)*K7),IF(M7="Void",0,""))) | O7: =IF(OR(M7="Win",M7="Loss"),IF(F7="Bet",K7,(I7-1)*K7),"")
A8: 46276 | B8: Bordertown | C8: 1 | D8: 6 | E8: Gradivus | F8: Lay | G8: Lay | H8: 4.9 | I8: 3.3 | J8: -0.1004 | K8: 1 | L8: 4 | M8: Win | N8: =IF(M8="Win",IF(F8="Bet",(I8-1)*K8,K8),IF(M8="Loss",IF(F8="Bet",-K8,-(I8-1)*K8),IF(M8="Void",0,""))) | O8: =IF(OR(M8="Win",M8="Loss"),IF(F8="Bet",K8,(I8-1)*K8),"")
A9: 46276 | B9: Bordertown | C9: 3 | D9: 6 | E9: Splash Of White | F9: Bet | G9: Bet | H9: 7.6 | I9: 9.5 | J9: 0.0258 | K9: 1 | L9: 6 | M9: Loss | N9: =IF(M9="Win",IF(F9="Bet",(I9-1)*K9,K9),IF(M9="Loss",IF(F9="Bet",-K9,-(I9-1)*K9),IF(M9="Void",0,""))) | O9: =IF(OR(M9="Win",M9="Loss"),IF(F9="Bet",K9,(I9-1)*K9),"")
A10: 46276 | B10: Tuncurry | C10: 3 | D10: 1 | E10: Sea Level | F10: Lay | G10: Lay | H10: 2.25 | I10: 1.75 | J10: -0.1224 | K10: 1 | L10: 1 | M10: Loss | N10: =IF(M10="Win",IF(F10="Bet",(I10-1)*K10,K10),IF(M10="Loss",IF(F10="Bet",-K10,-(I10-1)*K10),IF(M10="Void",0,""))) | O10: =IF(OR(M10="Win",M10="Loss"),IF(F10="Bet",K10,(I10-1)*K10),"")
A11: 46276 | B11: Tuncurry | C11: 7 | D11: 1 | E11: It's A Knockout | F11: Bet | G11: Bet | H11: 6.5 | I11: 8.5 | J11: 0.0354 | K11: 1 | L11: 5 | M11: Loss | N11: =IF(M11="Win",IF(F11="Bet",(I11-1)*K11,K11),IF(M11="Loss",IF(F11="Bet",-K11,-(I11-1)*K11),IF(M11="Void",0,""))) | O11: =IF(OR(M11="Win",M11="Loss"),IF(F11="Bet",K11,(I11-1)*K11),"")
A12: 46276 | B12: Tuncurry | C12: 8 | D12: 13 | E12: Andrea | F12: Lay | G12: Lay | H12: 2.35 | I12: 1.75 | J12: -0.144 | K12: 1 | L12: 1 | M12: Loss | N12: =IF(M12="Win",IF(F12="Bet",(I12-1)*K12,K12),IF(M12="Loss",IF(F12="Bet",-K12,-(I12-1)*K12),IF(M12="Void",0,""))) | O12: =IF(OR(M12="Win",M12="Loss"),IF(F12="Bet",K12,(I12-1)*K12),"")
A13: 46276 | B13: Goulburn | C13: 2 | D13: 6 | E13: Spain | F13: Lay | G13: Lay | H13: 1.65 | I13: 1.35 | J13: -0.1291 | K13: 1 | L13: 1 | M13: Loss | N13: =IF(M13="Win",IF(F13="Bet",(I13-1)*K13,K13),IF(M13="Loss",IF(F13="Bet",-K13,-(I13-1)*K13),IF(M13="Void",0,""))) | O13: =IF(OR(M13="Win",M13="Loss"),IF(F13="Bet",K13,(I13-1)*K13),"")
A14: 46276 | B14: Goulburn | C14: 3 | D14: 10 | E14: Montresor | F14: Lay | G14: Lay | H14: 2.4 | I14: 1.83 | J14: -0.1254 | K14: 1 | L14: 2 | M14: Win | N14: =IF(M14="Win",IF(F14="Bet",(I14-1)*K14,K14),IF(M14="Loss",IF(F14="Bet",-K14,-(I14-1)*K14),IF(M14="Void",0,""))) | O14: =IF(OR(M14="Win",M14="Loss"),IF(F14="Bet",K14,(I14-1)*K14),"")
A15: 46276 | B15: Sunshine Coast | C15: 1 | D15: 1 | E15: Sealord | F15: Bet | G15: Prime | H15: 3.3 | I15: 4.2 | J15: 0.0617 | K15: 1 | L15: 4 | M15: Loss | N15: =IF(M15="Win",IF(F15="Bet",(I15-1)*K15,K15),IF(M15="Loss",IF(F15="Bet",-K15,-(I15-1)*K15),IF(M15="Void",0,""))) | O15: =IF(OR(M15="Win",M15="Loss"),IF(F15="Bet",K15,(I15-1)*K15),"")
A16: 46276 | B16: Sunshine Coast | C16: 1 | D16: 5 | E16: Amelioration | F16: Lay | G16: Lay | H16: 3 | I16: 2.25 | J16: -0.1152 | K16: 1 | L16: 3 | M16: Win | N16: =IF(M16="Win",IF(F16="Bet",(I16-1)*K16,K16),IF(M16="Loss",IF(F16="Bet",-K16,-(I16-1)*K16),IF(M16="Void",0,""))) | O16: =IF(OR(M16="Win",M16="Loss"),IF(F16="Bet",K16,(I16-1)*K16),"")
A17: 46276 | B17: Sunshine Coast | C17: 8 | D17: 5 | E17: Brass Band | F17: Bet | G17: Bet | H17: 4.8 | I17: 6 | J17: 0.0432 | K17: 1 | L17: 3 | M17: Loss | N17: =IF(M17="Win",IF(F17="Bet",(I17-1)*K17,K17),IF(M17="Loss",IF(F17="Bet",-K17,-(I17-1)*K17),IF(M17="Void",0,""))) | O17: =IF(OR(M17="Win",M17="Loss"),IF(F17="Bet",K17,(I17-1)*K17),"")
... A66: 46277 | B66: Carnarvon | C66: 1 | D66: 1 | E66: Another Nephew | F66: Bet | G66: Bet | H66: 3.3 | I66: 4.06 | J66: 0.039 | K66: 1 | L66: 1 | M66: Win | N66: =IF(M66="Win",IF(F66="Bet",(I66-1)*K66,K66),IF(M66="Loss",IF(F66="Bet",-K66,-(I66-1)*K66),IF(M66="Void",0,""))) | O66: =IF(OR(M66="Win",M66="Loss"),IF(F66="Bet",K66,(I66-1)*K66),"")
A67: 46277 | B67: Toowoomba | C67: 1 | D67: 11 | E67: Crypto Miss | F67: Lay | G67: Lay | H67: 4.3 | I67: 2.8 | J67: -0.1219 | K67: 1 | L67: Unplaced | M67: Win | N67: =IF(M67="Win",IF(F67="Bet",(I67-1)*K67,K67),IF(M67="Loss",IF(F67="Bet",-K67,-(I67-1)*K67),IF(M67="Void",0,""))) | O67: =IF(OR(M67="Win",M67="Loss"),IF(F67="Bet",K67,(I67-1)*K67),"")
A68: 46277 | B68: Toowoomba | C68: 6 | D68: 8 | E68: Shrimpton | F68: Bet | G68: Bet | H68: 4.4 | I68: 5.4 | J68: 0.0291 | K68: 1 | L68: 1 | M68: Win | N68: =IF(M68="Win",IF(F68="Bet",(I68-1)*K68,K68),IF(M68="Loss",IF(F68="Bet",-K68,-(I68-1)*K68),IF(M68="Void",0,""))) | O68: =IF(OR(M68="Win",M68="Loss"),IF(F68="Bet",K68,(I68-1)*K68),"")
A69: 46277 | B69: Flemington | C69: 2 | D69: 5 | E69: Lara Antipova | F69: Bet | G69: Prime | H69: 6.4 | I69: 9.92 | J69: 0.0501 | K69: 1 | L69: 1 | M69: Win | N69: =IF(M69="Win",IF(F69="Bet",(I69-1)*K69,K69),IF(M69="Loss",IF(F69="Bet",-K69,-(I69-1)*K69),IF(M69="Void",0,""))) | O69: =IF(OR(M69="Win",M69="Loss"),IF(F69="Bet",K69,(I69-1)*K69),"")
A70: 46277 | B70: Mackay | C70: 2 | D70: 4 | E70: Elegant Venus | F70: Bet | G70: Bet | H70: 3 | I70: 3.46 | J70: 0.0257 | K70: 1 | L70: 1 | M70: Win | N70: =IF(M70="Win",IF(F70="Bet",(I70-1)*K70,K70),IF(M70="Loss",IF(F70="Bet",-K70,-(I70-1)*K70),IF(M70="Void",0,""))) | O70: =IF(OR(M70="Win",M70="Loss"),IF(F70="Bet",K70,(I70-1)*K70),"")
A71: 46277 | B71: Alice Springs | C71: 2 | D71: 2 | E71: Grinzinger Lass | F71: Bet | G71: Bet | H71: 4.2 | I71: 5.22 | J71: 0.0321 | K71: 1 | L71: 4 | M71: Loss | N71: =IF(M71="Win",IF(F71="Bet",(I71-1)*K71,K71),IF(M71="Loss",IF(F71="Bet",-K71,-(I71-1)*K71),IF(M71="Void",0,""))) | O71: =IF(OR(M71="Win",M71="Loss"),IF(F71="Bet",K71,(I71-1)*K71),"")
A72: 46278 | B72: Dalby | C72: 4 | D72: 6 | E72: Lady Willpower | F72: Lay | G72: Lay | H72: 1.45 | I72: 1.22 | J72: -0.1281 | K72: 1 | L72: 1 | M72: Loss | N72: =IF(M72="Win",IF(F72="Bet",(I72-1)*K72,K72),IF(M72="Loss",IF(F72="Bet",-K72,-(I72-1)*K72),IF(M72="Void",0,""))) | O72: =IF(OR(M72="Win",M72="Loss"),IF(F72="Bet",K72,(I72-1)*K72),"")
A73: 46278 | B73: Dalby | C73: 6 | D73: 4 | E73: Solo Hunter | F73: Lay | G73: Lay | H73: 1.7 | I73: 1.4 | J73: -0.1297 | K73: 1 | L73: 1 | M73: Loss | N73: =IF(M73="Win",IF(F73="Bet",(I73-1)*K73,K73),IF(M73="Loss",IF(F73="Bet",-K73,-(I73-1)*K73),IF(M73="Void",0,""))) | O73: =IF(OR(M73="Win",M73="Loss"),IF(F73="Bet",K73,(I73-1)*K73),"")
A74: 46278 | B74: Dalby | C74: 8 | D74: 8 | E74: Snugg | F74: Lay | G74: Lay | H74: 3.5 | I74: 2.6 | J74: -0.0974 | K74: 1 | L74: 3 | M74: Win | N74: =IF(M74="Win",IF(F74="Bet",(I74-1)*K74,K74),IF(M74="Loss",IF(F74="Bet",-K74,-(I74-1)*K74),IF(M74="Void",0,""))) | O74: =IF(OR(M74="Win",M74="Loss"),IF(F74="Bet",K74,(I74-1)*K74),"")
A75: 46278 | B75: Sale | C75: 1 | D75: 4 | E75: Mr Margolin | F75: Lay | G75: Lay | H75: 5.8 | I75: 3.7 | J75: -0.0966 | K75: 1 | L75: 1 | M75: Loss | N75: =IF(M75="Win",IF(F75="Bet",(I75-1)*K75,K75),IF(M75="Loss",IF(F75="Bet",-K75,-(I75-1)*K75),IF(M75="Void",0,""))) | O75: =IF(OR(M75="Win",M75="Loss"),IF(F75="Bet",K75,(I75-1)*K75),"")
A76: 46278 | B76: Sale | C76: 3 | D76: 12 | E76: Zendarina | F76: Lay | G76: Lay | H76: 3.7 | I76: 2.7 | J76: -0.0974 | K76: 1 | L76: 1 | M76: Loss | N76: =IF(M76="Win",IF(F76="Bet",(I76-1)*K76,K76),IF(M76="Loss",IF(F76="Bet",-K76,-(I76-1)*K76),IF(M76="Void",0,""))) | O76: =IF(OR(M76="Win",M76="Loss"),IF(F76="Bet",K76,(I76-1)*K76),"")
A77: 46278 | B77: Sale | C77: 4 | D77: 12 | E77: Classic Secret | F77: Lay | G77: Lay | H77: 3.5 | I77: 2.75 | J77: -0.0759 | K77: 1 | L77: 10 | M77: Win | N77: =IF(M77="Win",IF(F77="Bet",(I77-1)*K77,K77),IF(M77="Loss",IF(F77="Bet",-K77,-(I77-1)*K77),IF(M77="Void",0,""))) | O77: =IF(OR(M77="Win",M77="Loss"),IF(F77="Bet",K77,(I77-1)*K77),"")
A78: 46278 | B78: Sale | C78: 6 | D78: 4 | E78: Exfortythree | F78: Bet | G78: Bet | H78: 4.3 | I78: 5 | J78: 0.0351 | K78: 1 | L78: 5 | M78: Loss | N78: =IF(M78="Win",IF(F78="Bet",(I78-1)*K78,K78),IF(M78="Loss",IF(F78="Bet",-K78,-(I78-1)*K78),IF(M78="Void",0,""))) | O78: =IF(OR(M78="Win",M78="Loss"),IF(F78="Bet",K78,(I78-1)*K78),"")
A79: 46278 | B79: Coffs Harbour | C79: 3 | D79: 10 | E79: Magic Snitzel | F79: Lay | G79: Lay | H79: 3.1 | I79: 2.26 | J79: -0.0605 | K79: 1 | L79: 4 | M79: Win | N79: =IF(M79="Win",IF(F79="Bet",(I79-1)*K79,K79),IF(M79="Loss",IF(F79="Bet",-K79,-(I79-1)*K79),IF(M79="Void",0,""))) | O79: =IF(OR(M79="Win",M79="Loss"),IF(F79="Bet",K79,(I79-1)*K79),"")
... A89: 46278 | B89: Northam | C89: 1 | D89: 1 | E89: Who's Bent | F89: Bet | G89: Bet | H89: 3.5 | I89: 4.2 | J89: 0.0477 | K89: 1 | L89: 1 | M89: Win | N89: =IF(M89="Win",IF(F89="Bet",(I89-1)*K89,K89),IF(M89="Loss",IF(F89="Bet",-K89,-(I89-1)*K89),IF(M89="Void",0,""))) | O89: =IF(OR(M89="Win",M89="Loss"),IF(F89="Bet",K89,(I89-1)*K89),"")
A90: 46278 | B90: Bathurst | C90: 7 | D90: 2 | E90: Fearn Trick | F90: Bet | G90: Bet | H90: 7.5 | I90: 9.5 | J90: 0.0279 | K90: 1 | M90: Void | N90: =IF(M90="Win",IF(F90="Bet",(I90-1)*K90,K90),IF(M90="Loss",IF(F90="Bet",-K90,-(I90-1)*K90),IF(M90="Void",0,""))) | O90: =IF(OR(M90="Win",M90="Loss"),IF(F90="Bet",K90,(I90-1)*K90),"")
A91: 46278 | B91: Dalby | C91: 3 | D91: 4 | E91: Royal Diplomat | F91: Lay | G91: Lay | H91: 2.35 | I91: 2.05 | J91: -0.0632 | K91: 1 | L91: 1 | M91: Loss | N91: =IF(M91="Win",IF(F91="Bet",(I91-1)*K91,K91),IF(M91="Loss",IF(F91="Bet",-K91,-(I91-1)*K91),IF(M91="Void",0,""))) | O91: =IF(OR(M91="Win",M91="Loss"),IF(F91="Bet",K91,(I91-1)*K91),"")
A92: 46278 | B92: Sale | C92: 5 | D92: 10 | E92: Rhyme Dust | F92: Lay | G92: Lay | H92: 5.2 | I92: 3.7 | J92: -0.0787 | K92: 1 | L92: 9 | M92: Win | N92: =IF(M92="Win",IF(F92="Bet",(I92-1)*K92,K92),IF(M92="Loss",IF(F92="Bet",-K92,-(I92-1)*K92),IF(M92="Void",0,""))) | O92: =IF(OR(M92="Win",M92="Loss"),IF(F92="Bet",K92,(I92-1)*K92),"")
A93: 46279 | B93: Hamilton | C93: 3 | D93: 1 | E93: Asal | F93: Lay | G93: Lay | H93: 2.65 | I93: 2.1 | J93: -0.1008 | K93: 1 | L93: 1 | M93: Loss | N93: =IF(M93="Win",IF(F93="Bet",(I93-1)*K93,K93),IF(M93="Loss",IF(F93="Bet",-K93,-(I93-1)*K93),IF(M93="Void",0,""))) | O93: =IF(OR(M93="Win",M93="Loss"),IF(F93="Bet",K93,(I93-1)*K93),"")
A94: 46279 | B94: Hamilton | C94: 8 | D94: 6 | E94: Share The Stars | F94: Lay | G94: Lay | H94: 5.6 | I94: 3.5 | J94: -0.1079 | K94: 1 | L94: 8 | M94: Win | N94: =IF(M94="Win",IF(F94="Bet",(I94-1)*K94,K94),IF(M94="Loss",IF(F94="Bet",-K94,-(I94-1)*K94),IF(M94="Void",0,""))) | O94: =IF(OR(M94="Win",M94="Loss"),IF(F94="Bet",K94,(I94-1)*K94),"")
A95: 46279 | B95: Tamworth | C95: 1 | D95: 4 | E95: Heapy's Legacy | F95: Lay | G95: Lay | H95: 3.2 | I95: 2.4 | J95: -0.1061 | K95: 1 | L95: 3 | M95: Win | N95: =IF(M95="Win",IF(F95="Bet",(I95-1)*K95,K95),IF(M95="Loss",IF(F95="Bet",-K95,-(I95-1)*K95),IF(M95="Void",0,""))) | O95: =IF(OR(M95="Win",M95="Loss"),IF(F95="Bet",K95,(I95-1)*K95),"")
A96: 46279 | B96: Tamworth | C96: 2 | D96: 4 | E96: Sammaan City | F96: Lay | G96: Lay | H96: 2.05 | I96: 1.7 | J96: -0.1013 | K96: 1 | L96: 6 | M96: Win | N96: =IF(M96="Win",IF(F96="Bet",(I96-1)*K96,K96),IF(M96="Loss",IF(F96="Bet",-K96,-(I96-1)*K96),IF(M96="Void",0,""))) | O96: =IF(OR(M96="Win",M96="Loss"),IF(F96="Bet",K96,(I96-1)*K96),"")
A97: 46279 | B97: Tamworth | C97: 4 | D97: 2 | E97: Mongolian Master | F97: Bet | G97: Bet | H97: 6.9 | I97: 9.6 | J97: 0.0335 | K97: 1 | L97: 3 | M97: Loss | N97: =IF(M97="Win",IF(F97="Bet",(I97-1)*K97,K97),IF(M97="Loss",IF(F97="Bet",-K97,-(I97-1)*K97),IF(M97="Void",0,""))) | O97: =IF(OR(M97="Win",M97="Loss"),IF(F97="Bet",K97,(I97-1)*K97),"")
A98: 46279 | B98: Tamworth | C98: 5 | D98: 1 | E98: Dunquin | F98: Lay | G98: Lay | H98: 3.3 | I98: 2.2 | J98: -0.1514 | K98: 1 | L98: 2 | M98: Win | N98: =IF(M98="Win",IF(F98="Bet",(I98-1)*K98,K98),IF(M98="Loss",IF(F98="Bet",-K98,-(I98-1)*K98),IF(M98="Void",0,""))) | O98: =IF(OR(M98="Win",M98="Loss"),IF(F98="Bet",K98,(I98-1)*K98),"")
A99: 46279 | B99: Tamworth | C99: 6 | D99: 2 | E99: He's My Warrior | F99: Bet | G99: Bet | H99: 6.5 | I99: 8 | J99: 0.0286 | K99: 1 | L99: 6 | M99: Loss | N99: =IF(M99="Win",IF(F99="Bet",(I99-1)*K99,K99),IF(M99="Loss",IF(F99="Bet",-K99,-(I99-1)*K99),IF(M99="Void",0,""))) | O99: =IF(OR(M99="Win",M99="Loss"),IF(F99="Bet",K99,(I99-1)*K99),"")
...

Sheet Bets
O2: Bets
O3: Every bet, 11 Sep to 2 Oct 2026
A5: Date | B5: Track | C5: Race | D5: No. | E5: Horse | F5: Call | G5: Tag | H5: Rated $ | I5: Price $ | J5: Edge | K5: Stake (u) | L5: Finish | M5: Result | N5: Profit (u) | O5: At risk (u)
A6: 46276 | B6: Geelong | C6: 2 | D6: 5 | E6: Vespasian | F6: Bet | G6: Bet | H6: 6.3 | I6: 9.8 | J6: 0.0253 | K6: 1 | L6: 2 | M6: Loss | N6: =IF(M6="Win",IF(F6="Bet",(I6-1)*K6,K6),IF(M6="Loss",IF(F6="Bet",-K6,-(I6-1)*K6),IF(M6="Void",0,""))) | O6: =IF(OR(M6="Win",M6="Loss"),IF(F6="Bet",K6,(I6-1)*K6),"")
A7: 46276 | B7: Bordertown | C7: 3 | D7: 6 | E7: Splash Of White | F7: Bet | G7: Bet | H7: 7.6 | I7: 9.5 | J7: 0.0258 | K7: 1 | L7: 6 | M7: Loss | N7: =IF(M7="Win",IF(F7="Bet",(I7-1)*K7,K7),IF(M7="Loss",IF(F7="Bet",-K7,-(I7-1)*K7),IF(M7="Void",0,""))) | O7: =IF(OR(M7="Win",M7="Loss"),IF(F7="Bet",K7,(I7-1)*K7),"")
A8: 46276 | B8: Tuncurry | C8: 7 | D8: 1 | E8: It's A Knockout | F8: Bet | G8: Bet | H8: 6.5 | I8: 8.5 | J8: 0.0354 | K8: 1 | L8: 5 | M8: Loss | N8: =IF(M8="Win",IF(F8="Bet",(I8-1)*K8,K8),IF(M8="Loss",IF(F8="Bet",-K8,-(I8-1)*K8),IF(M8="Void",0,""))) | O8: =IF(OR(M8="Win",M8="Loss"),IF(F8="Bet",K8,(I8-1)*K8),"")
A9: 46276 | B9: Sunshine Coast | C9: 1 | D9: 1 | E9: Sealord | F9: Bet | G9: Prime | H9: 3.3 | I9: 4.2 | J9: 0.0617 | K9: 1 | L9: 4 | M9: Loss | N9: =IF(M9="Win",IF(F9="Bet",(I9-1)*K9,K9),IF(M9="Loss",IF(F9="Bet",-K9,-(I9-1)*K9),IF(M9="Void",0,""))) | O9: =IF(OR(M9="Win",M9="Loss"),IF(F9="Bet",K9,(I9-1)*K9),"")
A10: 46276 | B10: Sunshine Coast | C10: 8 | D10: 5 | E10: Brass Band | F10: Bet | G10: Bet | H10: 4.8 | I10: 6 | J10: 0.0432 | K10: 1 | L10: 3 | M10: Loss | N10: =IF(M10="Win",IF(F10="Bet",(I10-1)*K10,K10),IF(M10="Loss",IF(F10="Bet",-K10,-(I10-1)*K10),IF(M10="Void",0,""))) | O10: =IF(OR(M10="Win",M10="Loss"),IF(F10="Bet",K10,(I10-1)*K10),"")
A11: 46277 | B11: Gold Coast | C11: 8 | D11: 5 | E11: Lumens Lenny | F11: Bet | G11: Bet | H11: 5 | I11: 6.2 | J11: 0.0338 | K11: 1 | L11: 1 | M11: Win | N11: =IF(M11="Win",IF(F11="Bet",(I11-1)*K11,K11),IF(M11="Loss",IF(F11="Bet",-K11,-(I11-1)*K11),IF(M11="Void",0,""))) | O11: =IF(OR(M11="Win",M11="Loss"),IF(F11="Bet",K11,(I11-1)*K11),"")
A12: 46277 | B12: Flemington | C12: 3 | D12: 9 | E12: Lucky Brook | F12: Bet | G12: Bet | H12: 5.8 | I12: 7.5 | J12: 0.0382 | K12: 1 | L12: 8 | M12: Loss | N12: =IF(M12="Win",IF(F12="Bet",(I12-1)*K12,K12),IF(M12="Loss",IF(F12="Bet",-K12,-(I12-1)*K12),IF(M12="Void",0,""))) | O12: =IF(OR(M12="Win",M12="Loss"),IF(F12="Bet",K12,(I12-1)*K12),"")
A13: 46277 | B13: Flemington | C13: 6 | D13: 1 | E13: Cafe Millenium | F13: Bet | G13: Bet | H13: 5.5 | I13: 8.2 | J13: 0.0489 | K13: 1 | L13: 3 | M13: Loss | N13: =IF(M13="Win",IF(F13="Bet",(I13-1)*K13,K13),IF(M13="Loss",IF(F13="Bet",-K13,-(I13-1)*K13),IF(M13="Void",0,""))) | O13: =IF(OR(M13="Win",M13="Loss"),IF(F13="Bet",K13,(I13-1)*K13),"")
A14: 46277 | B14: Rosehill | C14: 2 | D14: 7 | E14: Formal | F14: Bet | G14: Bet | H14: 6.3 | I14: 9.68 | J14: 0.0348 | K14: 1 | L14: 1 | M14: Win | N14: =IF(M14="Win",IF(F14="Bet",(I14-1)*K14,K14),IF(M14="Loss",IF(F14="Bet",-K14,-(I14-1)*K14),IF(M14="Void",0,""))) | O14: =IF(OR(M14="Win",M14="Loss"),IF(F14="Bet",K14,(I14-1)*K14),"")
A15: 46277 | B15: Rosehill | C15: 3 | D15: 4 | E15: Golden Century | F15: Bet | G15: Prime | H15: 3.3 | I15: 5.13 | J15: 0.0958 | K15: 1 | L15: 4 | M15: Loss | N15: =IF(M15="Win",IF(F15="Bet",(I15-1)*K15,K15),IF(M15="Loss",IF(F15="Bet",-K15,-(I15-1)*K15),IF(M15="Void",0,""))) | O15: =IF(OR(M15="Win",M15="Loss"),IF(F15="Bet",K15,(I15-1)*K15),"")
A16: 46277 | B16: Rosehill | C16: 7 | D16: 2 | E16: Lazzura | F16: Bet | G16: Prime | H16: 2.55 | I16: 3.25 | J16: 0.0597 | K16: 1 | L16: 3 | M16: Loss | N16: =IF(M16="Win",IF(F16="Bet",(I16-1)*K16,K16),IF(M16="Loss",IF(F16="Bet",-K16,-(I16-1)*K16),IF(M16="Void",0,""))) | O16: =IF(OR(M16="Win",M16="Loss"),IF(F16="Bet",K16,(I16-1)*K16),"")
A17: 46277 | B17: Doomben | C17: 3 | D17: 4 | E17: Perfect Play | F17: Bet | G17: Bet | H17: 4.7 | I17: 5.72 | J17: 0.0319 | K17: 1 | L17: 4 | M17: Loss | N17: =IF(M17="Win",IF(F17="Bet",(I17-1)*K17,K17),IF(M17="Loss",IF(F17="Bet",-K17,-(I17-1)*K17),IF(M17="Void",0,""))) | O17: =IF(OR(M17="Win",M17="Loss"),IF(F17="Bet",K17,(I17-1)*K17),"")
... A40: 46278 | B40: Northam | C40: 1 | D40: 1 | E40: Who's Bent | F40: Bet | G40: Bet | H40: 3.5 | I40: 4.2 | J40: 0.0477 | K40: 1 | L40: 1 | M40: Win | N40: =IF(M40="Win",IF(F40="Bet",(I40-1)*K40,K40),IF(M40="Loss",IF(F40="Bet",-K40,-(I40-1)*K40),IF(M40="Void",0,""))) | O40: =IF(OR(M40="Win",M40="Loss"),IF(F40="Bet",K40,(I40-1)*K40),"")
A41: 46278 | B41: Bathurst | C41: 7 | D41: 2 | E41: Fearn Trick | F41: Bet | G41: Bet | H41: 7.5 | I41: 9.5 | J41: 0.0279 | K41: 1 | M41: Void | N41: =IF(M41="Win",IF(F41="Bet",(I41-1)*K41,K41),IF(M41="Loss",IF(F41="Bet",-K41,-(I41-1)*K41),IF(M41="Void",0,""))) | O41: =IF(OR(M41="Win",M41="Loss"),IF(F41="Bet",K41,(I41-1)*K41),"")
A42: 46279 | B42: Tamworth | C42: 4 | D42: 2 | E42: Mongolian Master | F42: Bet | G42: Bet | H42: 6.9 | I42: 9.6 | J42: 0.0335 | K42: 1 | L42: 3 | M42: Loss | N42: =IF(M42="Win",IF(F42="Bet",(I42-1)*K42,K42),IF(M42="Loss",IF(F42="Bet",-K42,-(I42-1)*K42),IF(M42="Void",0,""))) | O42: =IF(OR(M42="Win",M42="Loss"),IF(F42="Bet",K42,(I42-1)*K42),"")
A43: 46279 | B43: Tamworth | C43: 6 | D43: 2 | E43: He's My Warrior | F43: Bet | G43: Bet | H43: 6.5 | I43: 8 | J43: 0.0286 | K43: 1 | L43: 6 | M43: Loss | N43: =IF(M43="Win",IF(F43="Bet",(I43-1)*K43,K43),IF(M43="Loss",IF(F43="Bet",-K43,-(I43-1)*K43),IF(M43="Void",0,""))) | O43: =IF(OR(M43="Win",M43="Loss"),IF(F43="Bet",K43,(I43-1)*K43),"")
A44: 46279 | B44: Corowa | C44: 3 | D44: 2 | E44: Canny Hell | F44: Bet | G44: Prime | H44: 2.55 | I44: 3.95 | J44: 0.0792 | K44: 1 | L44: 2 | M44: Loss | N44: =IF(M44="Win",IF(F44="Bet",(I44-1)*K44,K44),IF(M44="Loss",IF(F44="Bet",-K44,-(I44-1)*K44),IF(M44="Void",0,""))) | O44: =IF(OR(M44="Win",M44="Loss"),IF(F44="Bet",K44,(I44-1)*K44),"")
A45: 46280 | B45: Moruya | C45: 5 | D45: 2 | E45: Nights Inferno | F45: Bet | G45: Bet | H45: 5.5 | I45: 6.8 | J45: 0.0271 | K45: 1 | L45: 4 | M45: Loss | N45: =IF(M45="Win",IF(F45="Bet",(I45-1)*K45,K45),IF(M45="Loss",IF(F45="Bet",-K45,-(I45-1)*K45),IF(M45="Void",0,""))) | O45: =IF(OR(M45="Win",M45="Loss"),IF(F45="Bet",K45,(I45-1)*K45),"")
A46: 46280 | B46: Bowen | C46: 1 | D46: 4 | E46: Missile Baby | F46: Bet | G46: Prime | H46: 4.1 | I46: 6.22 | J46: 0.0647 | K46: 1 | L46: 3 | M46: Loss | N46: =IF(M46="Win",IF(F46="Bet",(I46-1)*K46,K46),IF(M46="Loss",IF(F46="Bet",-K46,-(I46-1)*K46),IF(M46="Void",0,""))) | O46: =IF(OR(M46="Win",M46="Loss"),IF(F46="Bet",K46,(I46-1)*K46),"")
A47: 46281 | B47: Doomben | C47: 1 | D47: 1 | E47: Bacetti | F47: Bet | G47: Bet | H47: 6.1 | I47: 9.54 | J47: 0.0296 | K47: 1 | L47: 3 | M47: Loss | N47: =IF(M47="Win",IF(F47="Bet",(I47-1)*K47,K47),IF(M47="Loss",IF(F47="Bet",-K47,-(I47-1)*K47),IF(M47="Void",0,""))) | O47: =IF(OR(M47="Win",M47="Loss"),IF(F47="Bet",K47,(I47-1)*K47),"")
A48: 46281 | B48: Caulfield Heath | C48: 4 | D48: 13 | E48: Tuzemak | F48: Bet | G48: Bet | H48: 9.7 | I48: 17 | J48: 0.026 | K48: 1 | L48: 6 | M48: Loss | N48: =IF(M48="Win",IF(F48="Bet",(I48-1)*K48,K48),IF(M48="Loss",IF(F48="Bet",-K48,-(I48-1)*K48),IF(M48="Void",0,""))) | O48: =IF(OR(M48="Win",M48="Loss"),IF(F48="Bet",K48,(I48-1)*K48),"")
A49: 46281 | B49: Caulfield Heath | C49: 2 | D49: 4 | E49: All Business | F49: Bet | G49: Bet | H49: 6 | I49: 7.5 | J49: 0.0335 | K49: 1 | L49: 1 | M49: Win | N49: =IF(M49="Win",IF(F49="Bet",(I49-1)*K49,K49),IF(M49="Loss",IF(F49="Bet",-K49,-(I49-1)*K49),IF(M49="Void",0,""))) | O49: =IF(OR(M49="Win",M49="Loss"),IF(F49="Bet",K49,(I49-1)*K49),"")
A50: 46281 | B50: Belmont | C50: 2 | D50: 1 | E50: Rocking In Vegas | F50: Bet | G50: Prime | H50: 4.6 | I50: 14.5 | J50: 0.1018 | K50: 1 | L50: 3 | M50: Loss | N50: =IF(M50="Win",IF(F50="Bet",(I50-1)*K50,K50),IF(M50="Loss",IF(F50="Bet",-K50,-(I50-1)*K50),IF(M50="Void",0,""))) | O50: =IF(OR(M50="Win",M50="Loss"),IF(F50="Bet",K50,(I50-1)*K50),"")
A51: 46281 | B51: Belmont | C51: 3 | D51: 4 | E51: Wiluna Lass | F51: Bet | G51: Bet | H51: 4.3 | I51: 5.5 | J51: 0.0264 | K51: 1 | L51: 1 | M51: Win | N51: =IF(M51="Win",IF(F51="Bet",(I51-1)*K51,K51),IF(M51="Loss",IF(F51="Bet",-K51,-(I51-1)*K51),IF(M51="Void",0,""))) | O51: =IF(OR(M51="Win",M51="Loss"),IF(F51="Bet",K51,(I51-1)*K51),"")
A52: 46281 | B52: Launceston | C52: 2 | D52: 3 | E52: Lin Thizzy | F52: Bet | G52: Bet | H52: 3.4 | I52: 8.6 | J52: 0.0414 | K52: 1 | L52: 1 | M52: Win | N52: =IF(M52="Win",IF(F52="Bet",(I52-1)*K52,K52),IF(M52="Loss",IF(F52="Bet",-K52,-(I52-1)*K52),IF(M52="Void",0,""))) | O52: =IF(OR(M52="Win",M52="Loss"),IF(F52="Bet",K52,(I52-1)*K52),"")
A53: 46281 | B53: Canterbury | C53: 2 | D53: 6 | E53: Saffron Veil | F53: Bet | G53: Bet | H53: 1.8 | I53: 2.1 | J53: 0.0407 | K53: 1 | L53: 1 | M53: Win | N53: =IF(M53="Win",IF(F53="Bet",(I53-1)*K53,K53),IF(M53="Loss",IF(F53="Bet",-K53,-(I53-1)*K53),IF(M53="Void",0,""))) | O53: =IF(OR(M53="Win",M53="Loss"),IF(F53="Bet",K53,(I53-1)*K53),"")
... A55: 46281 | B55: Balaklava | C55: 1 | D55: 5 | E55: Leading Ride | F55: Bet | G55: Bet | H55: 4.6 | I55: 10.98 | J55: 0.037 | K55: 1 | L55: 3 | M55: Loss | N55: =IF(M55="Win",IF(F55="Bet",(I55-1)*K55,K55),IF(M55="Loss",IF(F55="Bet",-K55,-(I55-1)*K55),IF(M55="Void",0,""))) | O55: =IF(OR(M55="Win",M55="Loss"),IF(F55="Bet",K55,(I55-1)*K55),"")
A56: 46281 | B56: Caulfield Heath | C56: 2 | D56: 2 | E56: Lake Vostok | F56: Bet | G56: Bet | H56: 5.6 | I56: 7 | J56: 0.0355 | K56: 1 | M56: Void | N56: =IF(M56="Win",IF(F56="Bet",(I56-1)*K56,K56),IF(M56="Loss",IF(F56="Bet",-K56,-(I56-1)*K56),IF(M56="Void",0,""))) | O56: =IF(OR(M56="Win",M56="Loss"),IF(F56="Bet",K56,(I56-1)*K56),"")
A57: 46281 | B57: Caulfield Heath | C57: 1 | D57: 1 | E57: Corviglia | F57: Bet | G57: Prime | H57: 5.3 | I57: 9.36 | J57: 0.065 | K57: 1 | L57: 2 | M57: Loss | N57: =IF(M57="Win",IF(F57="Bet",(I57-1)*K57,K57),IF(M57="Loss",IF(F57="Bet",-K57,-(I57-1)*K57),IF(M57="Void",0,""))) | O57: =IF(OR(M57="Win",M57="Loss"),IF(F57="Bet",K57,(I57-1)*K57),"")
A58: 46281 | B58: Balaklava | C58: 1 | D58: 1 | E58: Sidebar | F58: Bet | G58: Bet | H58: 5.9 | I58: 10.5 | J58: 0.0262 | K58: 1 | L58: 4 | M58: Loss | N58: =IF(M58="Win",IF(F58="Bet",(I58-1)*K58,K58),IF(M58="Loss",IF(F58="Bet",-K58,-(I58-1)*K58),IF(M58="Void",0,""))) | O58: =IF(OR(M58="Win",M58="Loss"),IF(F58="Bet",K58,(I58-1)*K58),"")
A59: 46281 | B59: Doomben | C59: 3 | D59: 9 | E59: Flaressence | F59: Bet | G59: Bet | H59: 3.9 | I59: 6 | J59: 0.0388 | K59: 1 | L59: 2 | M59: Loss | N59: =IF(M59="Win",IF(F59="Bet",(I59-1)*K59,K59),IF(M59="Loss",IF(F59="Bet",-K59,-(I59-1)*K59),IF(M59="Void",0,""))) | O59: =IF(OR(M59="Win",M59="Loss"),IF(F59="Bet",K59,(I59-1)*K59),"")
A60: 46281 | B60: Caulfield Heath | C60: 7 | D60: 4 | E60: Rhapsody Chic | F60: Bet | G60: Bet | H60: 11.7 | I60: 31 | J60: 0.0264 | K60: 1 | L60: 8 | M60: Loss | N60: =IF(M60="Win",IF(F60="Bet",(I60-1)*K60,K60),IF(M60="Loss",IF(F60="Bet",-K60,-(I60-1)*K60),IF(M60="Void",0,""))) | O60: =IF(OR(M60="Win",M60="Loss"),IF(F60="Bet",K60,(I60-1)*K60),"")
A61: 46281 | B61: Canterbury | C61: 5 | D61: 1 | E61: Tremonti | F61: Bet | G61: Bet | H61: 9.1 | I61: 21 | J61: 0.0426 | K61: 1 | L61: 10 | M61: Loss | N61: =IF(M61="Win",IF(F61="Bet",(I61-1)*K61,K61),IF(M61="Loss",IF(F61="Bet",-K61,-(I61-1)*K61),IF(M61="Void",0,""))) | O61: =IF(OR(M61="Win",M61="Loss"),IF(F61="Bet",K61,(I61-1)*K61),"")
A62: 46281 | B62: Balaklava | C62: 8 | D62: 1 | E62: Super Lad | F62: Bet | G62: Bet | H62: 5.2 | I62: 6 | J62: 0.0257 | K62: 1 | L62: 5 | M62: Loss | N62: =IF(M62="Win",IF(F62="Bet",(I62-1)*K62,K62),IF(M62="Loss",IF(F62="Bet",-K62,-(I62-1)*K62),IF(M62="Void",0,""))) | O62: =IF(OR(M62="Win",M62="Loss"),IF(F62="Bet",K62,(I62-1)*K62),"")
A63: 46281 | B63: Doomben | C63: 5 | D63: 3 | E63: Captain Eagle | F63: Bet | G63: Bet | H63: 8.6 | I63: 11 | J63: 0.0252 | K63: 1 | L63: 8 | M63: Loss | N63: =IF(M63="Win",IF(F63="Bet",(I63-1)*K63,K63),IF(M63="Loss",IF(F63="Bet",-K63,-(I63-1)*K63),IF(M63="Void",0,""))) | O63: =IF(OR(M63="Win",M63="Loss"),IF(F63="Bet",K63,(I63-1)*K63),"")
A64: 46281 | B64: Canterbury | C64: 7 | D64: 9 | E64: Rileycat | F64: Bet | G64: Bet | H64: 11.7 | I64: 17 | J64: 0.027 | K64: 1 | L64: 10 | M64: Loss | N64: =IF(M64="Win",IF(F64="Bet",(I64-1)*K64,K64),IF(M64="Loss",IF(F64="Bet",-K64,-(I64-1)*K64),IF(M64="Void",0,""))) | O64: =IF(OR(M64="Win",M64="Loss"),IF(F64="Bet",K64,(I64-1)*K64),"")
A65: 46281 | B65: Caulfield Heath | C65: 7 | D65: 3 | E65: Angland | F65: Bet | G65: Bet | H65: 10.3 | I65: 14 | J65: 0.0255 | K65: 1 | L65: 3 | M65: Loss | N65: =IF(M65="Win",IF(F65="Bet",(I65-1)*K65,K65),IF(M65="Loss",IF(F65="Bet",-K65,-(I65-1)*K65),IF(M65="Void",0,""))) | O65: =IF(OR(M65="Win",M65="Loss"),IF(F65="Bet",K65,(I65-1)*K65),"")
...

Sheet Lays
O2: Lays
O3: Every lay, 11 Sep to 2 Oct 2026
A5: Date | B5: Track | C5: Race | D5: No. | E5: Horse | F5: Call | G5: Tag | H5: Rated $ | I5: Price $ | J5: Edge | K5: Stake (u) | L5: Finish | M5: Result | N5: Profit (u) | O5: At risk (u)
A6: 46276 | B6: Geelong | C6: 6 | D6: 10 | E6: Karren | F6: Lay | G6: Lay | H6: 2.85 | I6: 1.98 | J6: -0.1505 | K6: 1 | L6: 2 | M6: Win | N6: =IF(M6="Win",IF(F6="Bet",(I6-1)*K6,K6),IF(M6="Loss",IF(F6="Bet",-K6,-(I6-1)*K6),IF(M6="Void",0,""))) | O6: =IF(OR(M6="Win",M6="Loss"),IF(F6="Bet",K6,(I6-1)*K6),"")
A7: 46276 | B7: Bordertown | C7: 1 | D7: 6 | E7: Gradivus | F7: Lay | G7: Lay | H7: 4.9 | I7: 3.3 | J7: -0.1004 | K7: 1 | L7: 4 | M7: Win | N7: =IF(M7="Win",IF(F7="Bet",(I7-1)*K7,K7),IF(M7="Loss",IF(F7="Bet",-K7,-(I7-1)*K7),IF(M7="Void",0,""))) | O7: =IF(OR(M7="Win",M7="Loss"),IF(F7="Bet",K7,(I7-1)*K7),"")
A8: 46276 | B8: Tuncurry | C8: 3 | D8: 1 | E8: Sea Level | F8: Lay | G8: Lay | H8: 2.25 | I8: 1.75 | J8: -0.1224 | K8: 1 | L8: 1 | M8: Loss | N8: =IF(M8="Win",IF(F8="Bet",(I8-1)*K8,K8),IF(M8="Loss",IF(F8="Bet",-K8,-(I8-1)*K8),IF(M8="Void",0,""))) | O8: =IF(OR(M8="Win",M8="Loss"),IF(F8="Bet",K8,(I8-1)*K8),"")
A9: 46276 | B9: Tuncurry | C9: 8 | D9: 13 | E9: Andrea | F9: Lay | G9: Lay | H9: 2.35 | I9: 1.75 | J9: -0.144 | K9: 1 | L9: 1 | M9: Loss | N9: =IF(M9="Win",IF(F9="Bet",(I9-1)*K9,K9),IF(M9="Loss",IF(F9="Bet",-K9,-(I9-1)*K9),IF(M9="Void",0,""))) | O9: =IF(OR(M9="Win",M9="Loss"),IF(F9="Bet",K9,(I9-1)*K9),"")
A10: 46276 | B10: Goulburn | C10: 2 | D10: 6 | E10: Spain | F10: Lay | G10: Lay | H10: 1.65 | I10: 1.35 | J10: -0.1291 | K10: 1 | L10: 1 | M10: Loss | N10: =IF(M10="Win",IF(F10="Bet",(I10-1)*K10,K10),IF(M10="Loss",IF(F10="Bet",-K10,-(I10-1)*K10),IF(M10="Void",0,""))) | O10: =IF(OR(M10="Win",M10="Loss"),IF(F10="Bet",K10,(I10-1)*K10),"")
A11: 46276 | B11: Goulburn | C11: 3 | D11: 10 | E11: Montresor | F11: Lay | G11: Lay | H11: 2.4 | I11: 1.83 | J11: -0.1254 | K11: 1 | L11: 2 | M11: Win | N11: =IF(M11="Win",IF(F11="Bet",(I11-1)*K11,K11),IF(M11="Loss",IF(F11="Bet",-K11,-(I11-1)*K11),IF(M11="Void",0,""))) | O11: =IF(OR(M11="Win",M11="Loss"),IF(F11="Bet",K11,(I11-1)*K11),"")
A12: 46276 | B12: Sunshine Coast | C12: 1 | D12: 5 | E12: Amelioration | F12: Lay | G12: Lay | H12: 3 | I12: 2.25 | J12: -0.1152 | K12: 1 | L12: 3 | M12: Win | N12: =IF(M12="Win",IF(F12="Bet",(I12-1)*K12,K12),IF(M12="Loss",IF(F12="Bet",-K12,-(I12-1)*K12),IF(M12="Void",0,""))) | O12: =IF(OR(M12="Win",M12="Loss"),IF(F12="Bet",K12,(I12-1)*K12),"")
A13: 46277 | B13: Morphettville | C13: 4 | D13: 13 | E13: Harmonic Dancer | F13: Lay | G13: Lay | H13: 3.2 | I13: 1.73 | J13: -0.1087 | K13: 1 | L13: 3 | M13: Win | N13: =IF(M13="Win",IF(F13="Bet",(I13-1)*K13,K13),IF(M13="Loss",IF(F13="Bet",-K13,-(I13-1)*K13),IF(M13="Void",0,""))) | O13: =IF(OR(M13="Win",M13="Loss"),IF(F13="Bet",K13,(I13-1)*K13),"")
A14: 46277 | B14: Morphettville | C14: 6 | D14: 7 | E14: You Sexy Thing | F14: Lay | G14: Lay | H14: 3.8 | I14: 2.5 | J14: -0.1372 | K14: 1 | L14: 2 | M14: Win | N14: =IF(M14="Win",IF(F14="Bet",(I14-1)*K14,K14),IF(M14="Loss",IF(F14="Bet",-K14,-(I14-1)*K14),IF(M14="Void",0,""))) | O14: =IF(OR(M14="Win",M14="Loss"),IF(F14="Bet",K14,(I14-1)*K14),"")
A15: 46277 | B15: Flemington | C15: 6 | D15: 8 | E15: Sass Appeal | F15: Lay | G15: Lay | H15: 5.5 | I15: 3.4 | J15: -0.1121 | K15: 1 | L15: 4 | M15: Win | N15: =IF(M15="Win",IF(F15="Bet",(I15-1)*K15,K15),IF(M15="Loss",IF(F15="Bet",-K15,-(I15-1)*K15),IF(M15="Void",0,""))) | O15: =IF(OR(M15="Win",M15="Loss"),IF(F15="Bet",K15,(I15-1)*K15),"")
A16: 46277 | B16: Flemington | C16: 7 | D16: 5 | E16: Oliveanotherday | F16: Lay | G16: Lay | H16: 2.45 | I16: 1.65 | J16: -0.1955 | K16: 1 | L16: 5 | M16: Win | N16: =IF(M16="Win",IF(F16="Bet",(I16-1)*K16,K16),IF(M16="Loss",IF(F16="Bet",-K16,-(I16-1)*K16),IF(M16="Void",0,""))) | O16: =IF(OR(M16="Win",M16="Loss"),IF(F16="Bet",K16,(I16-1)*K16),"")
A17: 46277 | B17: Flemington | C17: 8 | D17: 12 | E17: Sheza Alibi | F17: Lay | G17: Lay | H17: 2.1 | I17: 1.65 | J17: -0.1263 | K17: 1 | L17: 1 | M17: Loss | N17: =IF(M17="Win",IF(F17="Bet",(I17-1)*K17,K17),IF(M17="Loss",IF(F17="Bet",-K17,-(I17-1)*K17),IF(M17="Void",0,""))) | O17: =IF(OR(M17="Win",M17="Loss"),IF(F17="Bet",K17,(I17-1)*K17),"")
... A42: 46277 | B42: Alice Springs | C42: 5 | D42: 5 | E42: Mummsie | F42: Lay | G42: Lay | H42: 5 | I42: 3.2 | J42: -0.1117 | K42: 1 | L42: 1 | M42: Loss | N42: =IF(M42="Win",IF(F42="Bet",(I42-1)*K42,K42),IF(M42="Loss",IF(F42="Bet",-K42,-(I42-1)*K42),IF(M42="Void",0,""))) | O42: =IF(OR(M42="Win",M42="Loss"),IF(F42="Bet",K42,(I42-1)*K42),"")
A43: 46277 | B43: Toowoomba | C43: 1 | D43: 11 | E43: Crypto Miss | F43: Lay | G43: Lay | H43: 4.3 | I43: 2.8 | J43: -0.1219 | K43: 1 | L43: Unplaced | M43: Win | N43: =IF(M43="Win",IF(F43="Bet",(I43-1)*K43,K43),IF(M43="Loss",IF(F43="Bet",-K43,-(I43-1)*K43),IF(M43="Void",0,""))) | O43: =IF(OR(M43="Win",M43="Loss"),IF(F43="Bet",K43,(I43-1)*K43),"")
A44: 46278 | B44: Dalby | C44: 4 | D44: 6 | E44: Lady Willpower | F44: Lay | G44: Lay | H44: 1.45 | I44: 1.22 | J44: -0.1281 | K44: 1 | L44: 1 | M44: Loss | N44: =IF(M44="Win",IF(F44="Bet",(I44-1)*K44,K44),IF(M44="Loss",IF(F44="Bet",-K44,-(I44-1)*K44),IF(M44="Void",0,""))) | O44: =IF(OR(M44="Win",M44="Loss"),IF(F44="Bet",K44,(I44-1)*K44),"")
A45: 46278 | B45: Dalby | C45: 6 | D45: 4 | E45: Solo Hunter | F45: Lay | G45: Lay | H45: 1.7 | I45: 1.4 | J45: -0.1297 | K45: 1 | L45: 1 | M45: Loss | N45: =IF(M45="Win",IF(F45="Bet",(I45-1)*K45,K45),IF(M45="Loss",IF(F45="Bet",-K45,-(I45-1)*K45),IF(M45="Void",0,""))) | O45: =IF(OR(M45="Win",M45="Loss"),IF(F45="Bet",K45,(I45-1)*K45),"")
A46: 46278 | B46: Dalby | C46: 8 | D46: 8 | E46: Snugg | F46: Lay | G46: Lay | H46: 3.5 | I46: 2.6 | J46: -0.0974 | K46: 1 | L46: 3 | M46: Win | N46: =IF(M46="Win",IF(F46="Bet",(I46-1)*K46,K46),IF(M46="Loss",IF(F46="Bet",-K46,-(I46-1)*K46),IF(M46="Void",0,""))) | O46: =IF(OR(M46="Win",M46="Loss"),IF(F46="Bet",K46,(I46-1)*K46),"")
A47: 46278 | B47: Sale | C47: 1 | D47: 4 | E47: Mr Margolin | F47: Lay | G47: Lay | H47: 5.8 | I47: 3.7 | J47: -0.0966 | K47: 1 | L47: 1 | M47: Loss | N47: =IF(M47="Win",IF(F47="Bet",(I47-1)*K47,K47),IF(M47="Loss",IF(F47="Bet",-K47,-(I47-1)*K47),IF(M47="Void",0,""))) | O47: =IF(OR(M47="Win",M47="Loss"),IF(F47="Bet",K47,(I47-1)*K47),"")
A48: 46278 | B48: Sale | C48: 3 | D48: 12 | E48: Zendarina | F48: Lay | G48: Lay | H48: 3.7 | I48: 2.7 | J48: -0.0974 | K48: 1 | L48: 1 | M48: Loss | N48: =IF(M48="Win",IF(F48="Bet",(I48-1)*K48,K48),IF(M48="Loss",IF(F48="Bet",-K48,-(I48-1)*K48),IF(M48="Void",0,""))) | O48: =IF(OR(M48="Win",M48="Loss"),IF(F48="Bet",K48,(I48-1)*K48),"")
A49: 46278 | B49: Sale | C49: 4 | D49: 12 | E49: Classic Secret | F49: Lay | G49: Lay | H49: 3.5 | I49: 2.75 | J49: -0.0759 | K49: 1 | L49: 10 | M49: Win | N49: =IF(M49="Win",IF(F49="Bet",(I49-1)*K49,K49),IF(M49="Loss",IF(F49="Bet",-K49,-(I49-1)*K49),IF(M49="Void",0,""))) | O49: =IF(OR(M49="Win",M49="Loss"),IF(F49="Bet",K49,(I49-1)*K49),"")
A50: 46278 | B50: Coffs Harbour | C50: 3 | D50: 10 | E50: Magic Snitzel | F50: Lay | G50: Lay | H50: 3.1 | I50: 2.26 | J50: -0.0605 | K50: 1 | L50: 4 | M50: Win | N50: =IF(M50="Win",IF(F50="Bet",(I50-1)*K50,K50),IF(M50="Loss",IF(F50="Bet",-K50,-(I50-1)*K50),IF(M50="Void",0,""))) | O50: =IF(OR(M50="Win",M50="Loss"),IF(F50="Bet",K50,(I50-1)*K50),"")
A51: 46278 | B51: Coffs Harbour | C51: 7 | D51: 5 | E51: Jade Trees | F51: Lay | G51: Lay | H51: 2.35 | I51: 1.7 | J51: -0.1654 | K51: 1 | L51: 1 | M51: Loss | N51: =IF(M51="Win",IF(F51="Bet",(I51-1)*K51,K51),IF(M51="Loss",IF(F51="Bet",-K51,-(I51-1)*K51),IF(M51="Void",0,""))) | O51: =IF(OR(M51="Win",M51="Loss"),IF(F51="Bet",K51,(I51-1)*K51),"")
A52: 46278 | B52: Bathurst | C52: 1 | D52: 10 | E52: May The Force | F52: Lay | G52: Lay | H52: 3.9 | I52: 2.8 | J52: -0.0996 | K52: 1 | L52: 1 | M52: Loss | N52: =IF(M52="Win",IF(F52="Bet",(I52-1)*K52,K52),IF(M52="Loss",IF(F52="Bet",-K52,-(I52-1)*K52),IF(M52="Void",0,""))) | O52: =IF(OR(M52="Win",M52="Loss"),IF(F52="Bet",K52,(I52-1)*K52),"")
A53: 46278 | B53: Bathurst | C53: 5 | D53: 1 | E53: Inquiring Minds | F53: Lay | G53: Lay | H53: 4.8 | I53: 3.3 | J53: -0.0935 | K53: 1 | L53: 2 | M53: Win | N53: =IF(M53="Win",IF(F53="Bet",(I53-1)*K53,K53),IF(M53="Loss",IF(F53="Bet",-K53,-(I53-1)*K53),IF(M53="Void",0,""))) | O53: =IF(OR(M53="Win",M53="Loss"),IF(F53="Bet",K53,(I53-1)*K53),"")
A54: 46278 | B54: Bathurst | C54: 6 | D54: 16 | E54: Tom Vegas | F54: Lay | G54: Lay | H54: 5.7 | I54: 3.4 | J54: -0.1194 | K54: 1 | L54: 2 | M54: Win | N54: =IF(M54="Win",IF(F54="Bet",(I54-1)*K54,K54),IF(M54="Loss",IF(F54="Bet",-K54,-(I54-1)*K54),IF(M54="Void",0,""))) | O54: =IF(OR(M54="Win",M54="Loss"),IF(F54="Bet",K54,(I54-1)*K54),"")
A55: 46278 | B55: Dalby | C55: 3 | D55: 4 | E55: Royal Diplomat | F55: Lay | G55: Lay | H55: 2.35 | I55: 2.05 | J55: -0.0632 | K55: 1 | L55: 1 | M55: Loss | N55: =IF(M55="Win",IF(F55="Bet",(I55-1)*K55,K55),IF(M55="Loss",IF(F55="Bet",-K55,-(I55-1)*K55),IF(M55="Void",0,""))) | O55: =IF(OR(M55="Win",M55="Loss"),IF(F55="Bet",K55,(I55-1)*K55),"")
... A94: 46281 | B94: Belmont | C94: 7 | D94: 5 | E94: Vampi Queen | F94: Lay | G94: Lay | H94: 6 | I94: 2.5 | J94: -0.1913 | K94: 1 | L94: 1 | M94: Loss | N94: =IF(M94="Win",IF(F94="Bet",(I94-1)*K94,K94),IF(M94="Loss",IF(F94="Bet",-K94,-(I94-1)*K94),IF(M94="Void",0,""))) | O94: =IF(OR(M94="Win",M94="Loss"),IF(F94="Bet",K94,(I94-1)*K94),"")
A95: 46281 | B95: Canterbury | C95: 4 | D95: 8 | E95: Ertijaaj | F95: Lay | G95: Lay | H95: 10.4 | I95: 4.2 | J95: -0.1417 | K95: 1 | M95: Void | N95: =IF(M95="Win",IF(F95="Bet",(I95-1)*K95,K95),IF(M95="Loss",IF(F95="Bet",-K95,-(I95-1)*K95),IF(M95="Void",0,""))) | O95: =IF(OR(M95="Win",M95="Loss"),IF(F95="Bet",K95,(I95-1)*K95),"")
A96: 46281 | B96: Launceston | C96: 6 | D96: 3 | E96: Vinraam | F96: Lay | G96: Lay | H96: 7.1 | I96: 3.4 | J96: -0.1535 | K96: 1 | L96: 5 | M96: Win | N96: =IF(M96="Win",IF(F96="Bet",(I96-1)*K96,K96),IF(M96="Loss",IF(F96="Bet",-K96,-(I96-1)*K96),IF(M96="Void",0,""))) | O96: =IF(OR(M96="Win",M96="Loss"),IF(F96="Bet",K96,(I96-1)*K96),"")
A97: 46281 | B97: Launceston | C97: 6 | D97: 2 | E97: Bailed | F97: Lay | G97: Lay | H97: 5.5 | I97: 2.6 | J97: -0.1627 | K97: 1 | L97: 3 | M97: Win | N97: =IF(M97="Win",IF(F97="Bet",(I97-1)*K97,K97),IF(M97="Loss",IF(F97="Bet",-K97,-(I97-1)*K97),IF(M97="Void",0,""))) | O97: =IF(OR(M97="Win",M97="Loss"),IF(F97="Bet",K97,(I97-1)*K97),"")
A98: 46281 | B98: Balaklava | C98: 8 | D98: 8 | E98: Embellisher | F98: Lay | G98: Lay | H98: 7.3 | I98: 3.1 | J98: -0.1494 | K98: 1 | L98: 4 | M98: Win | N98: =IF(M98="Win",IF(F98="Bet",(I98-1)*K98,K98),IF(M98="Loss",IF(F98="Bet",-K98,-(I98-1)*K98),IF(M98="Void",0,""))) | O98: =IF(OR(M98="Win",M98="Loss"),IF(F98="Bet",K98,(I98-1)*K98),"")
A99: 46281 | B99: Belmont | C99: 6 | D99: 7 | E99: Streamlined | F99: Lay | G99: Lay | H99: 3.1 | I99: 2.25 | J99: -0.1047 | K99: 1 | L99: 1 | M99: Loss | N99: =IF(M99="Win",IF(F99="Bet",(I99-1)*K99,K99),IF(M99="Loss",IF(F99="Bet",-K99,-(I99-1)*K99),IF(M99="Void",0,""))) | O99: =IF(OR(M99="Win",M99="Loss"),IF(F99="Bet",K99,(I99-1)*K99),"")
A100: 46281 | B100: Doomben | C100: 5 | D100: 1 | E100: Global Eclipse | F100: Lay | G100: Lay | H100: 4 | I100: 2.9 | J100: -0.1072 | K100: 1 | L100: 1 | M100: Loss | N100: =IF(M100="Win",IF(F100="Bet",(I100-1)*K100,K100),IF(M100="Loss",IF(F100="Bet",-K100,-(I100-1)*K100),IF(M100="Void",0,""))) | O100: =IF(OR(M100="Win",M100="Loss"),IF(F100="Bet",K100,(I100-1)*K100),"")
A101: 46281 | B101: Doomben | C101: 6 | D101: 4 | E101: Lockyer | F101: Lay | G101: Lay | H101: 3.1 | I101: 2.25 | J101: -0.107 | K101: 1 | L101: 1 | M101: Loss | N101: =IF(M101="Win",IF(F101="Bet",(I101-1)*K101,K101),IF(M101="Loss",IF(F101="Bet",-K101,-(I101-1)*K101),IF(M101="Void",0,""))) | O101: =IF(OR(M101="Win",M101="Loss"),IF(F101="Bet",K101,(I101-1)*K101),"")
A102: 46281 | B102: Balaklava | C102: 10 | D102: 3 | E102: Uptown Monk | F102: Lay | G102: Lay | H102: 3.7 | I102: 2.4 | J102: -0.1074 | K102: 1 | L102: 1 | M102: Loss | N102: =IF(M102="Win",IF(F102="Bet",(I102-1)*K102,K102),IF(M102="Loss",IF(F102="Bet",-K102,-(I102-1)*K102),IF(M102="Void",0,""))) | O102: =IF(OR(M102="Win",M102="Loss"),IF(F102="Bet",K102,(I102-1)*K102),"")
A103: 46281 | B103: Canterbury | C103: 5 | D103: 8 | E103: Whatalegacy | F103: Lay | G103: Lay | H103: 2.85 | I103: 2.1 | J103: -0.1223 | K103: 1 | L103: 1 | M103: Loss | N103: =IF(M103="Win",IF(F103="Bet",(I103-1)*K103,K103),IF(M103="Loss",IF(F103="Bet",-K103,-(I103-1)*K103),IF(M103="Void",0,""))) | O103: =IF(OR(M103="Win",M103="Loss"),IF(F103="Bet",K103,(I103-1)*K103),"")
A104: 46282 | B104: Mornington | C104: 2 | D104: 4 | E104: Top Conti | F104: Lay | G104: Lay | H104: 2.45 | I104: 1.74 | J104: -0.1485 | K104: 1 | L104: 1 | M104: Loss | N104: =IF(M104="Win",IF(F104="Bet",(I104-1)*K104,K104),IF(M104="Loss",IF(F104="Bet",-K104,-(I104-1)*K104),IF(M104="Void",0,""))) | O104: =IF(OR(M104="Win",M104="Loss"),IF(F104="Bet",K104,(I104-1)*K104),"")
...
