Workbook

Sheet Overview
J2: Results
J3: ="Since "&TEXT(MIN(Data!A2:A20000),"d mmm yyyy")&". Updates hourly."
B6: ALL CALLS | E6: BETS | H6: LAYS
B7: =SUM(Data!$N$2:$N$20000) | E7: =SUMIFS(Data!$N$2:$N$20000,Data!$F$2:$F$20000,"Bet") | H7: =SUMIFS(Data!$N$2:$N$20000,Data!$F$2:$F$20000,"Lay")
B9: =IFERROR(COUNTIFS(Data!$M$2:$M$20000,"Win")+COUNTIFS(Data!$M$2:$M$20000,"Loss")&" settled, "&TEXT(COUNTIFS(Data!$M$2:$M$20000,"Win")/(COUNTIFS(Data!$M$2:$M$20000,"Win")+COUNTIFS(Data!$M$2:$M$20000,"Loss")),"0%")&" strike, "&TEXT(B7/SUM(Data!$K$2:$K$20000),"+0.0%;-0.0%")&" POT","") | E9: =IFERROR(COUNTIFS(Data!$M$2:$M$20000,"Win",Data!$F$2:$F$20000,"Bet")+COUNTIFS(Data!$M$2:$M$20000,"Loss",Data!$F$2:$F$20000,"Bet")&" settled, "&TEXT(COUNTIFS(Data!$M$2:$M$20000,"Win",Data!$F$2:$F$20000,"Bet")/(COUNTIFS(Data!$M$2:$M$20000,"Win",Data!$F$2:$F$20000,"Bet")+COUNTIFS(Data!$M$2:$M$20000,"Loss",Data!$F$2:$F$20000,"Bet")),"0%")&" strike, "&TEXT(E7/SUMIFS(Data!$K$2:$K$20000,Data!$F$2:$F$20000,"Bet"),"+0.0%;-0.0%")&" POT","") | H9: =IFERROR(COUNTIFS(Data!$M$2:$M$20000,"Win",Data!$F$2:$F$20000,"Lay")+COUNTIFS(Data!$M$2:$M$20000,"Loss",Data!$F$2:$F$20000,"Lay")&" settled, "&TEXT(COUNTIFS(Data!$M$2:$M$20000,"Win",Data!$F$2:$F$20000,"Lay")/(COUNTIFS(Data!$M$2:$M$20000,"Win",Data!$F$2:$F$20000,"Lay")+COUNTIFS(Data!$M$2:$M$20000,"Loss",Data!$F$2:$F$20000,"Lay")),"0%")&" strike, "&TEXT(H7/SUMIFS(Data!$K$2:$K$20000,Data!$F$2:$F$20000,"Lay"),"+0.0%;-0.0%")&" POT","")
A11: Level stakes: one unit a call, a tenth on a Way. Bets settle at the best of fixed odds, SP and BSP; lays at the shortest lay price or BSP.
A12: A lay wins one unit when the horse loses. POT is units won over units staked: one a call, a tenth on a Way. Calls on scratched horses and abandoned races are void and left out.
A13: Bets at $10 or more from 11 to 15 Sep are excluded: our ratings over-priced long shots until the 15 Sep fix.
A14: BY CALL
B15: Calls | C15: Won | D15: Lost | E15: Strike | F15: Profit (u) | G15: Staked (u) | H15: POT
A16: All calls | B16: =COUNTIFS(Data!$M$2:$M$20000,"<>") | C16: =COUNTIFS(Data!$M$2:$M$20000,"Win") | D16: =COUNTIFS(Data!$M$2:$M$20000,"Loss") | E16: =IF(C16+D16=0,"",C16/(C16+D16)) | F16: =SUM(Data!$N$2:$N$20000) | G16: =SUM(Data!$K$2:$K$20000) | H16: =IF(G16=0,"",F16/G16)
A17: Bets | B17: =COUNTIFS(Data!$M$2:$M$20000,"<>",Data!$F$2:$F$20000,"Bet") | C17: =COUNTIFS(Data!$M$2:$M$20000,"Win",Data!$F$2:$F$20000,"Bet") | D17: =COUNTIFS(Data!$M$2:$M$20000,"Loss",Data!$F$2:$F$20000,"Bet") | E17: =IF(C17+D17=0,"",C17/(C17+D17)) | F17: =SUMIFS(Data!$N$2:$N$20000,Data!$F$2:$F$20000,"Bet") | G17: =SUMIFS(Data!$K$2:$K$20000,Data!$F$2:$F$20000,"Bet") | H17: =IF(G17=0,"",F17/G17)
A18: Lays | B18: =COUNTIFS(Data!$M$2:$M$20000,"<>",Data!$F$2:$F$20000,"Lay") | C18: =COUNTIFS(Data!$M$2:$M$20000,"Win",Data!$F$2:$F$20000,"Lay") | D18: =COUNTIFS(Data!$M$2:$M$20000,"Loss",Data!$F$2:$F$20000,"Lay") | E18: =IF(C18+D18=0,"",C18/(C18+D18)) | F18: =SUMIFS(Data!$N$2:$N$20000,Data!$F$2:$F$20000,"Lay") | G18: =SUMIFS(Data!$K$2:$K$20000,Data!$F$2:$F$20000,"Lay") | H18: =IF(G18=0,"",F18/G18)
A20: BY TAG
A21: Tag | B21: Calls | C21: Won | D21: Lost | E21: Strike | F21: Profit (u) | G21: Staked (u) | H21: POT
A22: Prime | B22: =COUNTIFS(Data!$M$2:$M$20000,"<>",Data!$G$2:$G$20000,"Prime") | C22: =COUNTIFS(Data!$M$2:$M$20000,"Win",Data!$G$2:$G$20000,"Prime") | D22: =COUNTIFS(Data!$M$2:$M$20000,"Loss",Data!$G$2:$G$20000,"Prime") | E22: =IF(C22+D22=0,"",C22/(C22+D22)) | F22: =SUMIFS(Data!$N$2:$N$20000,Data!$G$2:$G$20000,"Prime") | G22: =SUMIFS(Data!$K$2:$K$20000,Data!$G$2:$G$20000,"Prime") | H22: =IF(G22=0,"",F22/G22)
A23: Bet | B23: =COUNTIFS(Data!$M$2:$M$20000,"<>",Data!$G$2:$G$20000,"Bet") | C23: =COUNTIFS(Data!$M$2:$M$20000,"Win",Data!$G$2:$G$20000,"Bet") | D23: =COUNTIFS(Data!$M$2:$M$20000,"Loss",Data!$G$2:$G$20000,"Bet") | E23: =IF(C23+D23=0,"",C23/(C23+D23)) | F23: =SUMIFS(Data!$N$2:$N$20000,Data!$G$2:$G$20000,"Bet") | G23: =SUMIFS(Data!$K$2:$K$20000,Data!$G$2:$G$20000,"Bet") | H23: =IF(G23=0,"",F23/G23)
A24: Way | B24: =COUNTIFS(Data!$M$2:$M$20000,"<>",Data!$G$2:$G$20000,"Way") | C24: =COUNTIFS(Data!$M$2:$M$20000,"Win",Data!$G$2:$G$20000,"Way") | D24: =COUNTIFS(Data!$M$2:$M$20000,"Loss",Data!$G$2:$G$20000,"Way") | E24: =IF(C24+D24=0,"",C24/(C24+D24)) | F24: =SUMIFS(Data!$N$2:$N$20000,Data!$G$2:$G$20000,"Way") | G24: =SUMIFS(Data!$K$2:$K$20000,Data!$G$2:$G$20000,"Way") | H24: =IF(G24=0,"",F24/G24)
A25: Lay | B25: =COUNTIFS(Data!$M$2:$M$20000,"<>",Data!$G$2:$G$20000,"Lay") | C25: =COUNTIFS(Data!$M$2:$M$20000,"Win",Data!$G$2:$G$20000,"Lay") | D25: =COUNTIFS(Data!$M$2:$M$20000,"Loss",Data!$G$2:$G$20000,"Lay") | E25: =IF(C25+D25=0,"",C25/(C25+D25)) | F25: =SUMIFS(Data!$N$2:$N$20000,Data!$G$2:$G$20000,"Lay") | G25: =SUMIFS(Data!$K$2:$K$20000,Data!$G$2:$G$20000,"Lay") | H25: =IF(G25=0,"",F25/G25)
A27: LAST 12 WEEKS
A28: Week of | B28: Calls | C28: Won | D28: Lost | E28: Strike | F28: Profit (u) | G28: Staked (u) | H28: POT
A29: =IFERROR(MAX(Data!$A$2:$A$20000)-WEEKDAY(MAX(Data!$A$2:$A$20000),3),"") | B29: =IF($A29="","",COUNTIFS(Data!$M$2:$M$20000,"<>",Data!$A$2:$A$20000,">="&$A29,Data!$A$2:$A$20000,"<"&($A29+7))) | C29: =IF($A29="","",COUNTIFS(Data!$M$2:$M$20000,"Win",Data!$A$2:$A$20000,">="&$A29,Data!$A$2:$A$20000,"<"&($A29+7))) | D29: =IF($A29="","",COUNTIFS(Data!$M$2:$M$20000,"Loss",Data!$A$2:$A$20000,">="&$A29,Data!$A$2:$A$20000,"<"&($A29+7))) | E29: =IF($A29="","",IF(C29+D29=0,"",C29/(C29+D29))) | F29: =IF($A29="","",SUMIFS(Data!$N$2:$N$20000,Data!$A$2:$A$20000,">="&$A29,Data!$A$2:$A$20000,"<"&($A29+7))) | G29: =IF($A29="","",SUMIFS(Data!$K$2:$K$20000,Data!$A$2:$A$20000,">="&$A29,Data!$A$2:$A$20000,"<"&($A29+7))) | H29: =IF($A29="","",IF(G29=0,"",F29/G29)) | L29: DAY BY DAY
A30: =IF(A29="","",IF(A29-7<MIN(Data!$A$2:$A$20000)-6,"",A29-7)) | B30: =IF($A30="","",COUNTIFS(Data!$M$2:$M$20000,"<>",Data!$A$2:$A$20000,">="&$A30,Data!$A$2:$A$20000,"<"&($A30+7))) | C30: =IF($A30="","",COUNTIFS(Data!$M$2:$M$20000,"Win",Data!$A$2:$A$20000,">="&$A30,Data!$A$2:$A$20000,"<"&($A30+7))) | D30: =IF($A30="","",COUNTIFS(Data!$M$2:$M$20000,"Loss",Data!$A$2:$A$20000,">="&$A30,Data!$A$2:$A$20000,"<"&($A30+7))) | E30: =IF($A30="","",IF(C30+D30=0,"",C30/(C30+D30))) | F30: =IF($A30="","",SUMIFS(Data!$N$2:$N$20000,Data!$A$2:$A$20000,">="&$A30,Data!$A$2:$A$20000,"<"&($A30+7))) | G30: =IF($A30="","",SUMIFS(Data!$K$2:$K$20000,Data!$A$2:$A$20000,">="&$A30,Data!$A$2:$A$20000,"<"&($A30+7))) | H30: =IF($A30="","",IF(G30=0,"",F30/G30)) | L30: Date | M30: Bets (u) | N30: Lays (u) | O30: Day (u) | P30: Running (u)
A31: =IF(A30="","",IF(A30-7<MIN(Data!$A$2:$A$20000)-6,"",A30-7)) | B31: =IF($A31="","",COUNTIFS(Data!$M$2:$M$20000,"<>",Data!$A$2:$A$20000,">="&$A31,Data!$A$2:$A$20000,"<"&($A31+7))) | C31: =IF($A31="","",COUNTIFS(Data!$M$2:$M$20000,"Win",Data!$A$2:$A$20000,">="&$A31,Data!$A$2:$A$20000,"<"&($A31+7))) | D31: =IF($A31="","",COUNTIFS(Data!$M$2:$M$20000,"Loss",Data!$A$2:$A$20000,">="&$A31,Data!$A$2:$A$20000,"<"&($A31+7))) | E31: =IF($A31="","",IF(C31+D31=0,"",C31/(C31+D31))) | F31: =IF($A31="","",SUMIFS(Data!$N$2:$N$20000,Data!$A$2:$A$20000,">="&$A31,Data!$A$2:$A$20000,"<"&($A31+7))) | G31: =IF($A31="","",SUMIFS(Data!$K$2:$K$20000,Data!$A$2:$A$20000,">="&$A31,Data!$A$2:$A$20000,"<"&($A31+7))) | H31: =IF($A31="","",IF(G31=0,"",F31/G31)) | L31: =IFERROR(SORT(UNIQUE(FILTER(Data!$A$2:$A$20000,Data!$A$2:$A$20000<>""))),"") | M31: =IF($L31="","",SUMIFS(Data!$N$2:$N$20000,Data!$A$2:$A$20000,$L31,Data!$F$2:$F$20000,"Bet")) | N31: =IF($L31="","",SUMIFS(Data!$N$2:$N$20000,Data!$A$2:$A$20000,$L31,Data!$F$2:$F$20000,"Lay")) | O31: =IF($L31="","",M31+N31) | P31: =IF($L31="","",SUMIFS(Data!$N$2:$N$20000,Data!$A$2:$A$20000,"<="&$L31))
A32: =IF(A31="","",IF(A31-7<MIN(Data!$A$2:$A$20000)-6,"",A31-7)) | B32: =IF($A32="","",COUNTIFS(Data!$M$2:$M$20000,"<>",Data!$A$2:$A$20000,">="&$A32,Data!$A$2:$A$20000,"<"&($A32+7))) | C32: =IF($A32="","",COUNTIFS(Data!$M$2:$M$20000,"Win",Data!$A$2:$A$20000,">="&$A32,Data!$A$2:$A$20000,"<"&($A32+7))) | D32: =IF($A32="","",COUNTIFS(Data!$M$2:$M$20000,"Loss",Data!$A$2:$A$20000,">="&$A32,Data!$A$2:$A$20000,"<"&($A32+7))) | E32: =IF($A32="","",IF(C32+D32=0,"",C32/(C32+D32))) | F32: =IF($A32="","",SUMIFS(Data!$N$2:$N$20000,Data!$A$2:$A$20000,">="&$A32,Data!$A$2:$A$20000,"<"&($A32+7))) | G32: =IF($A32="","",SUMIFS(Data!$K$2:$K$20000,Data!$A$2:$A$20000,">="&$A32,Data!$A$2:$A$20000,"<"&($A32+7))) | H32: =IF($A32="","",IF(G32=0,"",F32/G32)) | M32: =IF($L32="","",SUMIFS(Data!$N$2:$N$20000,Data!$A$2:$A$20000,$L32,Data!$F$2:$F$20000,"Bet")) | N32: =IF($L32="","",SUMIFS(Data!$N$2:$N$20000,Data!$A$2:$A$20000,$L32,Data!$F$2:$F$20000,"Lay")) | O32: =IF($L32="","",M32+N32) | P32: =IF($L32="","",SUMIFS(Data!$N$2:$N$20000,Data!$A$2:$A$20000,"<="&$L32))
A33: =IF(A32="","",IF(A32-7<MIN(Data!$A$2:$A$20000)-6,"",A32-7)) | B33: =IF($A33="","",COUNTIFS(Data!$M$2:$M$20000,"<>",Data!$A$2:$A$20000,">="&$A33,Data!$A$2:$A$20000,"<"&($A33+7))) | C33: =IF($A33="","",COUNTIFS(Data!$M$2:$M$20000,"Win",Data!$A$2:$A$20000,">="&$A33,Data!$A$2:$A$20000,"<"&($A33+7))) | D33: =IF($A33="","",COUNTIFS(Data!$M$2:$M$20000,"Loss",Data!$A$2:$A$20000,">="&$A33,Data!$A$2:$A$20000,"<"&($A33+7))) | E33: =IF($A33="","",IF(C33+D33=0,"",C33/(C33+D33))) | F33: =IF($A33="","",SUMIFS(Data!$N$2:$N$20000,Data!$A$2:$A$20000,">="&$A33,Data!$A$2:$A$20000,"<"&($A33+7))) | G33: =IF($A33="","",SUMIFS(Data!$K$2:$K$20000,Data!$A$2:$A$20000,">="&$A33,Data!$A$2:$A$20000,"<"&($A33+7))) | H33: =IF($A33="","",IF(G33=0,"",F33/G33)) | M33: =IF($L33="","",SUMIFS(Data!$N$2:$N$20000,Data!$A$2:$A$20000,$L33,Data!$F$2:$F$20000,"Bet")) | N33: =IF($L33="","",SUMIFS(Data!$N$2:$N$20000,Data!$A$2:$A$20000,$L33,Data!$F$2:$F$20000,"Lay")) | O33: =IF($L33="","",M33+N33) | P33: =IF($L33="","",SUMIFS(Data!$N$2:$N$20000,Data!$A$2:$A$20000,"<="&$L33))
A34: =IF(A33="","",IF(A33-7<MIN(Data!$A$2:$A$20000)-6,"",A33-7)) | B34: =IF($A34="","",COUNTIFS(Data!$M$2:$M$20000,"<>",Data!$A$2:$A$20000,">="&$A34,Data!$A$2:$A$20000,"<"&($A34+7))) | C34: =IF($A34="","",COUNTIFS(Data!$M$2:$M$20000,"Win",Data!$A$2:$A$20000,">="&$A34,Data!$A$2:$A$20000,"<"&($A34+7))) | D34: =IF($A34="","",COUNTIFS(Data!$M$2:$M$20000,"Loss",Data!$A$2:$A$20000,">="&$A34,Data!$A$2:$A$20000,"<"&($A34+7))) | E34: =IF($A34="","",IF(C34+D34=0,"",C34/(C34+D34))) | F34: =IF($A34="","",SUMIFS(Data!$N$2:$N$20000,Data!$A$2:$A$20000,">="&$A34,Data!$A$2:$A$20000,"<"&($A34+7))) | G34: =IF($A34="","",SUMIFS(Data!$K$2:$K$20000,Data!$A$2:$A$20000,">="&$A34,Data!$A$2:$A$20000,"<"&($A34+7))) | H34: =IF($A34="","",IF(G34=0,"",F34/G34)) | M34: =IF($L34="","",SUMIFS(Data!$N$2:$N$20000,Data!$A$2:$A$20000,$L34,Data!$F$2:$F$20000,"Bet")) | N34: =IF($L34="","",SUMIFS(Data!$N$2:$N$20000,Data!$A$2:$A$20000,$L34,Data!$F$2:$F$20000,"Lay")) | O34: =IF($L34="","",M34+N34) | P34: =IF($L34="","",SUMIFS(Data!$N$2:$N$20000,Data!$A$2:$A$20000,"<="&$L34))
A35: =IF(A34="","",IF(A34-7<MIN(Data!$A$2:$A$20000)-6,"",A34-7)) | B35: =IF($A35="","",COUNTIFS(Data!$M$2:$M$20000,"<>",Data!$A$2:$A$20000,">="&$A35,Data!$A$2:$A$20000,"<"&($A35+7))) | C35: =IF($A35="","",COUNTIFS(Data!$M$2:$M$20000,"Win",Data!$A$2:$A$20000,">="&$A35,Data!$A$2:$A$20000,"<"&($A35+7))) | D35: =IF($A35="","",COUNTIFS(Data!$M$2:$M$20000,"Loss",Data!$A$2:$A$20000,">="&$A35,Data!$A$2:$A$20000,"<"&($A35+7))) | E35: =IF($A35="","",IF(C35+D35=0,"",C35/(C35+D35))) | F35: =IF($A35="","",SUMIFS(Data!$N$2:$N$20000,Data!$A$2:$A$20000,">="&$A35,Data!$A$2:$A$20000,"<"&($A35+7))) | G35: =IF($A35="","",SUMIFS(Data!$K$2:$K$20000,Data!$A$2:$A$20000,">="&$A35,Data!$A$2:$A$20000,"<"&($A35+7))) | H35: =IF($A35="","",IF(G35=0,"",F35/G35)) | M35: =IF($L35="","",SUMIFS(Data!$N$2:$N$20000,Data!$A$2:$A$20000,$L35,Data!$F$2:$F$20000,"Bet")) | N35: =IF($L35="","",SUMIFS(Data!$N$2:$N$20000,Data!$A$2:$A$20000,$L35,Data!$F$2:$F$20000,"Lay")) | O35: =IF($L35="","",M35+N35) | P35: =IF($L35="","",SUMIFS(Data!$N$2:$N$20000,Data!$A$2:$A$20000,"<="&$L35))
A36: =IF(A35="","",IF(A35-7<MIN(Data!$A$2:$A$20000)-6,"",A35-7)) | B36: =IF($A36="","",COUNTIFS(Data!$M$2:$M$20000,"<>",Data!$A$2:$A$20000,">="&$A36,Data!$A$2:$A$20000,"<"&($A36+7))) | C36: =IF($A36="","",COUNTIFS(Data!$M$2:$M$20000,"Win",Data!$A$2:$A$20000,">="&$A36,Data!$A$2:$A$20000,"<"&($A36+7))) | D36: =IF($A36="","",COUNTIFS(Data!$M$2:$M$20000,"Loss",Data!$A$2:$A$20000,">="&$A36,Data!$A$2:$A$20000,"<"&($A36+7))) | E36: =IF($A36="","",IF(C36+D36=0,"",C36/(C36+D36))) | F36: =IF($A36="","",SUMIFS(Data!$N$2:$N$20000,Data!$A$2:$A$20000,">="&$A36,Data!$A$2:$A$20000,"<"&($A36+7))) | G36: =IF($A36="","",SUMIFS(Data!$K$2:$K$20000,Data!$A$2:$A$20000,">="&$A36,Data!$A$2:$A$20000,"<"&($A36+7))) | H36: =IF($A36="","",IF(G36=0,"",F36/G36)) | M36: =IF($L36="","",SUMIFS(Data!$N$2:$N$20000,Data!$A$2:$A$20000,$L36,Data!$F$2:$F$20000,"Bet")) | N36: =IF($L36="","",SUMIFS(Data!$N$2:$N$20000,Data!$A$2:$A$20000,$L36,Data!$F$2:$F$20000,"Lay")) | O36: =IF($L36="","",M36+N36) | P36: =IF($L36="","",SUMIFS(Data!$N$2:$N$20000,Data!$A$2:$A$20000,"<="&$L36))
A37: =IF(A36="","",IF(A36-7<MIN(Data!$A$2:$A$20000)-6,"",A36-7)) | B37: =IF($A37="","",COUNTIFS(Data!$M$2:$M$20000,"<>",Data!$A$2:$A$20000,">="&$A37,Data!$A$2:$A$20000,"<"&($A37+7))) | C37: =IF($A37="","",COUNTIFS(Data!$M$2:$M$20000,"Win",Data!$A$2:$A$20000,">="&$A37,Data!$A$2:$A$20000,"<"&($A37+7))) | D37: =IF($A37="","",COUNTIFS(Data!$M$2:$M$20000,"Loss",Data!$A$2:$A$20000,">="&$A37,Data!$A$2:$A$20000,"<"&($A37+7))) | E37: =IF($A37="","",IF(C37+D37=0,"",C37/(C37+D37))) | F37: =IF($A37="","",SUMIFS(Data!$N$2:$N$20000,Data!$A$2:$A$20000,">="&$A37,Data!$A$2:$A$20000,"<"&($A37+7))) | G37: =IF($A37="","",SUMIFS(Data!$K$2:$K$20000,Data!$A$2:$A$20000,">="&$A37,Data!$A$2:$A$20000,"<"&($A37+7))) | H37: =IF($A37="","",IF(G37=0,"",F37/G37)) | M37: =IF($L37="","",SUMIFS(Data!$N$2:$N$20000,Data!$A$2:$A$20000,$L37,Data!$F$2:$F$20000,"Bet")) | N37: =IF($L37="","",SUMIFS(Data!$N$2:$N$20000,Data!$A$2:$A$20000,$L37,Data!$F$2:$F$20000,"Lay")) | O37: =IF($L37="","",M37+N37) | P37: =IF($L37="","",SUMIFS(Data!$N$2:$N$20000,Data!$A$2:$A$20000,"<="&$L37))
A38: =IF(A37="","",IF(A37-7<MIN(Data!$A$2:$A$20000)-6,"",A37-7)) | B38: =IF($A38="","",COUNTIFS(Data!$M$2:$M$20000,"<>",Data!$A$2:$A$20000,">="&$A38,Data!$A$2:$A$20000,"<"&($A38+7))) | C38: =IF($A38="","",COUNTIFS(Data!$M$2:$M$20000,"Win",Data!$A$2:$A$20000,">="&$A38,Data!$A$2:$A$20000,"<"&($A38+7))) | D38: =IF($A38="","",COUNTIFS(Data!$M$2:$M$20000,"Loss",Data!$A$2:$A$20000,">="&$A38,Data!$A$2:$A$20000,"<"&($A38+7))) | E38: =IF($A38="","",IF(C38+D38=0,"",C38/(C38+D38))) | F38: =IF($A38="","",SUMIFS(Data!$N$2:$N$20000,Data!$A$2:$A$20000,">="&$A38,Data!$A$2:$A$20000,"<"&($A38+7))) | G38: =IF($A38="","",SUMIFS(Data!$K$2:$K$20000,Data!$A$2:$A$20000,">="&$A38,Data!$A$2:$A$20000,"<"&($A38+7))) | H38: =IF($A38="","",IF(G38=0,"",F38/G38)) | M38: =IF($L38="","",SUMIFS(Data!$N$2:$N$20000,Data!$A$2:$A$20000,$L38,Data!$F$2:$F$20000,"Bet")) | N38: =IF($L38="","",SUMIFS(Data!$N$2:$N$20000,Data!$A$2:$A$20000,$L38,Data!$F$2:$F$20000,"Lay")) | O38: =IF($L38="","",M38+N38) | P38: =IF($L38="","",SUMIFS(Data!$N$2:$N$20000,Data!$A$2:$A$20000,"<="&$L38))
A39: =IF(A38="","",IF(A38-7<MIN(Data!$A$2:$A$20000)-6,"",A38-7)) | B39: =IF($A39="","",COUNTIFS(Data!$M$2:$M$20000,"<>",Data!$A$2:$A$20000,">="&$A39,Data!$A$2:$A$20000,"<"&($A39+7))) | C39: =IF($A39="","",COUNTIFS(Data!$M$2:$M$20000,"Win",Data!$A$2:$A$20000,">="&$A39,Data!$A$2:$A$20000,"<"&($A39+7))) | D39: =IF($A39="","",COUNTIFS(Data!$M$2:$M$20000,"Loss",Data!$A$2:$A$20000,">="&$A39,Data!$A$2:$A$20000,"<"&($A39+7))) | E39: =IF($A39="","",IF(C39+D39=0,"",C39/(C39+D39))) | F39: =IF($A39="","",SUMIFS(Data!$N$2:$N$20000,Data!$A$2:$A$20000,">="&$A39,Data!$A$2:$A$20000,"<"&($A39+7))) | G39: =IF($A39="","",SUMIFS(Data!$K$2:$K$20000,Data!$A$2:$A$20000,">="&$A39,Data!$A$2:$A$20000,"<"&($A39+7))) | H39: =IF($A39="","",IF(G39=0,"",F39/G39)) | M39: =IF($L39="","",SUMIFS(Data!$N$2:$N$20000,Data!$A$2:$A$20000,$L39,Data!$F$2:$F$20000,"Bet")) | N39: =IF($L39="","",SUMIFS(Data!$N$2:$N$20000,Data!$A$2:$A$20000,$L39,Data!$F$2:$F$20000,"Lay")) | O39: =IF($L39="","",M39+N39) | P39: =IF($L39="","",SUMIFS(Data!$N$2:$N$20000,Data!$A$2:$A$20000,"<="&$L39))
A40: =IF(A39="","",IF(A39-7<MIN(Data!$A$2:$A$20000)-6,"",A39-7)) | B40: =IF($A40="","",COUNTIFS(Data!$M$2:$M$20000,"<>",Data!$A$2:$A$20000,">="&$A40,Data!$A$2:$A$20000,"<"&($A40+7))) | C40: =IF($A40="","",COUNTIFS(Data!$M$2:$M$20000,"Win",Data!$A$2:$A$20000,">="&$A40,Data!$A$2:$A$20000,"<"&($A40+7))) | D40: =IF($A40="","",COUNTIFS(Data!$M$2:$M$20000,"Loss",Data!$A$2:$A$20000,">="&$A40,Data!$A$2:$A$20000,"<"&($A40+7))) | E40: =IF($A40="","",IF(C40+D40=0,"",C40/(C40+D40))) | F40: =IF($A40="","",SUMIFS(Data!$N$2:$N$20000,Data!$A$2:$A$20000,">="&$A40,Data!$A$2:$A$20000,"<"&($A40+7))) | G40: =IF($A40="","",SUMIFS(Data!$K$2:$K$20000,Data!$A$2:$A$20000,">="&$A40,Data!$A$2:$A$20000,"<"&($A40+7))) | H40: =IF($A40="","",IF(G40=0,"",F40/G40)) | M40: =IF($L40="","",SUMIFS(Data!$N$2:$N$20000,Data!$A$2:$A$20000,$L40,Data!$F$2:$F$20000,"Bet")) | N40: =IF($L40="","",SUMIFS(Data!$N$2:$N$20000,Data!$A$2:$A$20000,$L40,Data!$F$2:$F$20000,"Lay")) | O40: =IF($L40="","",M40+N40) | P40: =IF($L40="","",SUMIFS(Data!$N$2:$N$20000,Data!$A$2:$A$20000,"<="&$L40))
M41: =IF($L41="","",SUMIFS(Data!$N$2:$N$20000,Data!$A$2:$A$20000,$L41,Data!$F$2:$F$20000,"Bet")) | N41: =IF($L41="","",SUMIFS(Data!$N$2:$N$20000,Data!$A$2:$A$20000,$L41,Data!$F$2:$F$20000,"Lay")) | O41: =IF($L41="","",M41+N41) | P41: =IF($L41="","",SUMIFS(Data!$N$2:$N$20000,Data!$A$2:$A$20000,"<="&$L41))
A42: theoverlay.com.au 18+ Gamble responsibly: 1800 858 858 or gamblinghelponline.org.au | M42: =IF($L42="","",SUMIFS(Data!$N$2:$N$20000,Data!$A$2:$A$20000,$L42,Data!$F$2:$F$20000,"Bet")) | N42: =IF($L42="","",SUMIFS(Data!$N$2:$N$20000,Data!$A$2:$A$20000,$L42,Data!$F$2:$F$20000,"Lay")) | O42: =IF($L42="","",M42+N42) | P42: =IF($L42="","",SUMIFS(Data!$N$2:$N$20000,Data!$A$2:$A$20000,"<="&$L42))
M43: =IF($L43="","",SUMIFS(Data!$N$2:$N$20000,Data!$A$2:$A$20000,$L43,Data!$F$2:$F$20000,"Bet")) | N43: =IF($L43="","",SUMIFS(Data!$N$2:$N$20000,Data!$A$2:$A$20000,$L43,Data!$F$2:$F$20000,"Lay")) | O43: =IF($L43="","",M43+N43) | P43: =IF($L43="","",SUMIFS(Data!$N$2:$N$20000,Data!$A$2:$A$20000,"<="&$L43))
M44: =IF($L44="","",SUMIFS(Data!$N$2:$N$20000,Data!$A$2:$A$20000,$L44,Data!$F$2:$F$20000,"Bet")) | N44: =IF($L44="","",SUMIFS(Data!$N$2:$N$20000,Data!$A$2:$A$20000,$L44,Data!$F$2:$F$20000,"Lay")) | O44: =IF($L44="","",M44+N44) | P44: =IF($L44="","",SUMIFS(Data!$N$2:$N$20000,Data!$A$2:$A$20000,"<="&$L44))
M45: =IF($L45="","",SUMIFS(Data!$N$2:$N$20000,Data!$A$2:$A$20000,$L45,Data!$F$2:$F$20000,"Bet")) | N45: =IF($L45="","",SUMIFS(Data!$N$2:$N$20000,Data!$A$2:$A$20000,$L45,Data!$F$2:$F$20000,"Lay")) | O45: =IF($L45="","",M45+N45) | P45: =IF($L45="","",SUMIFS(Data!$N$2:$N$20000,Data!$A$2:$A$20000,"<="&$L45))
M46: =IF($L46="","",SUMIFS(Data!$N$2:$N$20000,Data!$A$2:$A$20000,$L46,Data!$F$2:$F$20000,"Bet")) | N46: =IF($L46="","",SUMIFS(Data!$N$2:$N$20000,Data!$A$2:$A$20000,$L46,Data!$F$2:$F$20000,"Lay")) | O46: =IF($L46="","",M46+N46) | P46: =IF($L46="","",SUMIFS(Data!$N$2:$N$20000,Data!$A$2:$A$20000,"<="&$L46))
M47: =IF($L47="","",SUMIFS(Data!$N$2:$N$20000,Data!$A$2:$A$20000,$L47,Data!$F$2:$F$20000,"Bet")) | N47: =IF($L47="","",SUMIFS(Data!$N$2:$N$20000,Data!$A$2:$A$20000,$L47,Data!$F$2:$F$20000,"Lay")) | O47: =IF($L47="","",M47+N47) | P47: =IF($L47="","",SUMIFS(Data!$N$2:$N$20000,Data!$A$2:$A$20000,"<="&$L47))
...

Sheet All Calls
O2: All calls
O3: ="Since "&TEXT(MIN(Data!A2:A20000),"d mmm yyyy")&". Updates hourly."
A5: Date | B5: Track | C5: Race | D5: No. | E5: Horse | F5: Call | G5: Tag | H5: Rated $ | I5: Price $ | J5: Edge | K5: Stake (u) | L5: Finish | M5: Result | N5: Profit (u) | O5: Liability (u)
A6: =IFERROR(QUERY(Data!A2:O20000,"select * where Col1 is not null order by Col1 desc, Col2, Col3",0),"Loading results")

Sheet Bets
O2: Bets
O3: ="Since "&TEXT(MIN(Data!A2:A20000),"d mmm yyyy")&". Updates hourly."
A5: Date | B5: Track | C5: Race | D5: No. | E5: Horse | F5: Call | G5: Tag | H5: Rated $ | I5: Price $ | J5: Edge | K5: Stake (u) | L5: Finish | M5: Result | N5: Profit (u) | O5: Liability (u)
A6: =IFERROR(QUERY(Data!A2:O20000,"select * where Col1 is not null and Col6 = 'Bet' order by Col1 desc, Col2, Col3",0),"Loading results")

Sheet Lays
O2: Lays
O3: ="Since "&TEXT(MIN(Data!A2:A20000),"d mmm yyyy")&". Updates hourly."
A5: Date | B5: Track | C5: Race | D5: No. | E5: Horse | F5: Call | G5: Tag | H5: Rated $ | I5: Price $ | J5: Edge | K5: Stake (u) | L5: Finish | M5: Result | N5: Profit (u) | O5: Liability (u)
A6: =IFERROR(QUERY(Data!A2:O20000,"select * where Col1 is not null and Col6 = 'Lay' order by Col1 desc, Col2, Col3",0),"Loading results")

Sheet Data
A1: =IMPORTDATA("https://theoverlay.com.au/api/results.csv") | Q1: Pulled from theoverlay.com.au/api/results.csv, refreshed by Google about hourly. Do not type in this tab.
